<?xml version="1.0" ?>
<!-- =================================================================================== -->
<!-- |    This document was autogenerated by xacro from /home/obin/ws_public/src/PAPRAS-V0-Public/papras_simple_demo/urdf/simple_robot_7dof.urdf.xacro | -->
<!-- |    EDITING THIS FILE BY HAND IS NOT RECOMMENDED                                 | -->
<!-- =================================================================================== -->
<robot name="simple_robot">
    <!-- PAPRAS URDF Macros -->
    <!-- Main URDF File should contain:
        - world link
        - world-env joint
        - env link
        - env-robotn/link1 joint for each mount -->
    <!-- This file contains URDF geometry, transmission data and Gazebo references -->
    <material name="black">
        <color rgba="0.0 0.0 0.0 1.0" />
    </material>
    <material name="blue">
        <color rgba="0.0 0.0 0.8 1.0" />
    </material>
    <material name="green">
        <color rgba="0.0 0.8 0.0 1.0" />
    </material>
    <material name="grey">
        <color rgba="0.5 0.5 0.5 1.0" />
    </material>
    <material name="orange">
        <color rgba="1.0 0.4235294117647059 0.0392156862745098 1.0" />
    </material>
    <material name="brown">
        <color rgba="0.8705882352941177 0.8117647058823529 0.7647058823529411 1.0" />
    </material>
    <material name="red">
        <color rgba="0.8 0.0 0.0 1.0" />
    </material>
    <material name="white">
        <color rgba="1.0 1.0 1.0 1.0" />
    </material>
    <!-- Import all Gazebo-customization elements, including Gazebo colors -->
    <!-- World -->
    <gazebo reference="world">
        <plugin name="gazebo_ros_control" filename="libgazebo_ros_control.so">
            <robotNamespace>/</robotNamespace>
        </plugin>
    </gazebo>
    <!-- Evn Link -->
    <gazebo reference="env" />
    <!-- ros_control plugin -->
    <gazebo>
        <plugin filename="libgazebo_ros_control.so" name="gazebo_ros_control">
            <robotSimType>gazebo_ros_control/DefaultRobotHWSim</robotSimType>
        </plugin>
    </gazebo>
    <link name="world" />
    <joint name="robot1/env_arm_fixed" type="fixed">
        <parent link="world" />
        <child link="robot1/link1" />
        <origin rpy="0 0 0" xyz="0 0 0" />
    </joint>
    <!-- link 1 -->
    <link name="robot1/link1">
        <visual>
            <origin rpy="0 0 0" xyz="0 0 0" />
            <geometry>
                <mesh filename="package://papras_description/meshes/link1.stl" scale="0.001 0.001 0.001" />
            </geometry>
            <material name="grey" />
        </visual>
        <collision>
            <origin rpy="0 0 0" xyz="0 0 0" />
            <geometry>
                <mesh filename="package://papras_description/meshes/link1.stl" scale="0.001 0.001 0.001" />
            </geometry>
        </collision>
        <inertial>
            <origin xyz="-0.00205616406 0.00000000 0.07012969338" rpy="0 0 0" />
            <mass value="0.91200000" />
            <inertia ixx="0.00140582306367" ixy="0.00000000" ixz="0.00000000" iyy="0.00140582097352" iyz="-0.00000000" izz="0.00043779331105" />
        </inertial>
    </link>
    <gazebo reference="robot1/link1">
        <kp>1000000.0</kp>
        <kd>100.0</kd>
        <mu1>30.0</mu1>
        <mu2>30.0</mu2>
        <maxVel>1.0</maxVel>
        <minDepth>0.001</minDepth>
        <material>Gazebo/White</material>
        <selfCollide>1</selfCollide>
        <dampingFactor>0.01</dampingFactor>
    </gazebo>
    <!-- Joint 1 -->
    <joint name="robot1/joint1" type="revolute">
        <parent link="robot1/link1" />
        <child link="robot1/link2" />
        <origin rpy="0 0 0" xyz="0.0 0.0 0.126" />
        <axis xyz="0 0 1" />
        <limit effort="100" lower="-3.141592653589793" upper="3.141592653589793" velocity="3.03687" />
        <dynamics damping="0.7" />
    </joint>
    <transmission name="robot1/tran1">
        <type>transmission_interface/SimpleTransmission</type>
        <joint name="robot1/joint1">
            <hardwareInterface>hardware_interface/PositionJointInterface</hardwareInterface>
        </joint>
        <actuator name="robot1/motor1">
            <mechanicalReduction>1</mechanicalReduction>
            <hardwareInterface>hardware_interface/EffortJointInterface</hardwareInterface>
        </actuator>
    </transmission>
    <!-- link 2 -->
    <link name="robot1/link2">
        <visual>
            <origin rpy="0 0 0" xyz="0 0 0" />
            <geometry>
                <mesh filename="package://papras_description/meshes/link2.stl" scale="0.001 0.001 0.001" />
            </geometry>
            <material name="grey" />
        </visual>
        <collision>
            <origin rpy="0 0 0" xyz="0 0 0" />
            <geometry>
                <mesh filename="package://papras_description/meshes/link2.stl" scale="0.001 0.001 0.001" />
            </geometry>
        </collision>
        <inertial>
            <origin xyz="-0.00000000001 -0.01570756882 0.02819237930" rpy="0 0 0" />
            <mass value="0.88500000" />
            <inertia ixx="0.00155754725347" ixy="-0.00000000" ixz="-0.00000000" iyy="0.00048405544236" iyz="-0.00000173296990" izz="0.00154667193282" />
        </inertial>
    </link>
    <gazebo reference="robot1/link2">
        <kp>1000000.0</kp>
        <kd>100.0</kd>
        <mu1>30.0</mu1>
        <mu2>30.0</mu2>
        <maxVel>1.0</maxVel>
        <minDepth>0.001</minDepth>
        <material>Gazebo/White</material>
        <selfCollide>1</selfCollide>
        <dampingFactor>0.01</dampingFactor>
    </gazebo>
    <!-- Joint 2 -->
    <joint name="robot1/joint2" type="revolute">
        <parent link="robot1/link2" />
        <child link="robot1/link3" />
        <origin rpy="1.5707963267948966 -1.5707963267948966 0" xyz="0.0 0.00 0.033" />
        <axis xyz="0 0 1" />
        <limit effort="100" lower="-2.0" upper="2.0" velocity="3.03687" />
        <dynamics damping="0.7" />
    </joint>
    <transmission name="robot1/tran2">
        <type>transmission_interface/SimpleTransmission</type>
        <joint name="robot1/joint2">
            <hardwareInterface>hardware_interface/PositionJointInterface</hardwareInterface>
        </joint>
        <actuator name="robot1/motor2">
            <mechanicalReduction>1</mechanicalReduction>
            <hardwareInterface>hardware_interface/EffortJointInterface</hardwareInterface>
        </actuator>
    </transmission>
    <!-- link 2 -->
    <link name="robot1/link3">
        <visual>
            <origin rpy="0 0 0" xyz="0.0 0.0 0.0" />
            <geometry>
                <mesh filename="package://papras_description/meshes/7dof/link3.stl" />
            </geometry>
            <material name="grey" />
        </visual>
        <collision>
            <origin rpy="0 0 0" xyz="0 0 0" />
            <geometry>
                <mesh filename="package://papras_description/meshes/7dof/link3.stl" />
            </geometry>
        </collision>
        <inertial>
            <origin xyz="0.10300488 0.00026160 0.00111164" rpy="0 0 0" />
            <mass value="1.01000000" />
            <inertia ixx="0.00182373" ixy="-0.00000000" ixz="-0.00000526" iyy="0.00433189" iyz="0.00000000" izz="0.00310084" />
        </inertial>
    </link>
    <gazebo reference="robot1/link3">
        <kp>1000000.0</kp>
        <kd>100.0</kd>
        <mu1>30.0</mu1>
        <mu2>30.0</mu2>
        <maxVel>1.0</maxVel>
        <minDepth>0.001</minDepth>
        <material>Gazebo/White</material>
        <selfCollide>1</selfCollide>
        <dampingFactor>0.01</dampingFactor>
    </gazebo>
    <!-- Joint 2 -->
    <joint name="robot1/joint3" type="revolute">
        <parent link="robot1/link3" />
        <child link="robot1/link4" />
        <origin rpy="0 -1.5707963267948966 -1.5707963267948966" xyz="0.156382198147594 0 0.000400000000010851" />
        <axis xyz="0 1 0" />
        <limit effort="100" lower="-3.141592653589793" upper="3.141592653589793" velocity="3.03687" />
        <dynamics damping="0.7" />
    </joint>
    <transmission name="robot1/tran3">
        <type>transmission_interface/SimpleTransmission</type>
        <joint name="robot1/joint3">
            <hardwareInterface>hardware_interface/PositionJointInterface</hardwareInterface>
        </joint>
        <actuator name="robot1/motor3">
            <mechanicalReduction>1</mechanicalReduction>
            <hardwareInterface>hardware_interface/EffortJointInterface</hardwareInterface>
        </actuator>
    </transmission>
    <!-- link 2 -->
    <link name="robot1/link4">
        <visual>
            <origin rpy="0 0 0" xyz="0.0 0.0 0.0" />
            <geometry>
                <mesh filename="package://papras_description/meshes/7dof/link4.stl" />
            </geometry>
            <material name="grey" />
        </visual>
        <collision>
            <origin rpy="0 0 0" xyz="0 0 0" />
            <geometry>
                <mesh filename="package://papras_description/meshes/7dof/link4.stl" />
            </geometry>
        </collision>
        <inertial>
            <origin xyz="-0.00205466 0.07035925 0.01546531" rpy="0 0 0" />
            <mass value="0.96600000" />
            <inertia ixx="0.00180447" ixy="0.00000423" ixz="0.00000322" iyy="0.00132106" iyz="-0.00029745" izz="0.00211226" />
        </inertial>
    </link>
    <gazebo reference="robot1/link4">
        <kp>1000000.0</kp>
        <kd>100.0</kd>
        <mu1>30.0</mu1>
        <mu2>30.0</mu2>
        <maxVel>1.0</maxVel>
        <minDepth>0.001</minDepth>
        <material>Gazebo/White</material>
        <selfCollide>1</selfCollide>
        <dampingFactor>0.01</dampingFactor>
    </gazebo>
    <!-- Joint 3 -->
    <joint name="robot1/joint4" type="revolute">
        <parent link="robot1/link4" />
        <child link="robot1/link5" />
        <origin rpy="3.141592653589793 -1.5707963267948966 1.5707963267948966" xyz="0.0575 0.10761780185239 0.0300000000000553" />
        <axis xyz="0 1 0" />
        <limit effort="100" lower="-3.141592653589793" upper="1.42" velocity="3.03687" />
        <dynamics damping="0.7" />
    </joint>
    <transmission name="robot1/tran4">
        <type>transmission_interface/SimpleTransmission</type>
        <joint name="robot1/joint4">
            <hardwareInterface>hardware_interface/PositionJointInterface</hardwareInterface>
        </joint>
        <actuator name="robot1/motor4">
            <mechanicalReduction>1</mechanicalReduction>
            <hardwareInterface>hardware_interface/EffortJointInterface</hardwareInterface>
        </actuator>
    </transmission>
    <!-- link 5 -->
    <link name="robot1/link5">
        <visual>
            <origin rpy="0 0 3.14" xyz="0.227 0.0085 -0.024" />
            <geometry>
                <mesh filename="package://papras_description/meshes/link4_papras.stl" scale="0.001 0.001 0.001" />
            </geometry>
            <material name="grey" />
        </visual>
        <collision>
            <origin rpy="0 0 3.14" xyz="0.227 0.0085 -0.024" />
            <geometry>
                <mesh filename="package://papras_description/meshes/link4_papras_simple.stl" scale="0.001 0.001 0.001" />
            </geometry>
        </collision>
        <inertial>
            <origin xyz="0.133722 -0.058143 0.028408" rpy="0 0 0" />
            <!-- <origin xyz="${0.277-0.09327796} 0.06664315 0.05240824" rpy="0 0 3.14"/>                                                                   -->
            <mass value="1.22500000" />
            <inertia ixx="0.00184346" ixy="0.00000031" ixz="-0.00063174" iyy="0.00588246" iyz="0.00000015" izz="0.00647638" />
        </inertial>
    </link>
    <gazebo reference="robot1/link5">
        <kp>1000000.0</kp>
        <kd>100.0</kd>
        <mu1>30.0</mu1>
        <mu2>30.0</mu2>
        <maxVel>1.0</maxVel>
        <minDepth>0.001</minDepth>
        <material>Gazebo/White</material>
        <selfCollide>1</selfCollide>
        <dampingFactor>0.01</dampingFactor>
    </gazebo>
    <!-- Joint 4 -->
    <joint name="robot1/joint5" type="revolute">
        <parent link="robot1/link5" />
        <child link="robot1/link6" />
        <origin rpy="0 0 0" xyz="0.19500 -0.05750 0.03000" />
        <axis xyz="1 0 0" />
        <limit effort="100" lower="-2.748893571891069" upper="2.748893571891069" velocity="3.03687" />
        <dynamics damping="0.7" />
    </joint>
    <transmission name="robot1/tran5">
        <type>transmission_interface/SimpleTransmission</type>
        <joint name="robot1/joint5">
            <hardwareInterface>hardware_interface/PositionJointInterface</hardwareInterface>
        </joint>
        <actuator name="robot1/motor5">
            <mechanicalReduction>1</mechanicalReduction>
            <hardwareInterface>hardware_interface/EffortJointInterface</hardwareInterface>
        </actuator>
    </transmission>
    <!-- link 6 -->
    <link name="robot1/link6">
        <visual>
            <origin rpy="0 0 0" xyz="0 0 0" />
            <geometry>
                <mesh filename="package://papras_description/meshes/link5.stl" scale="0.001 0.001 0.001" />
            </geometry>
            <material name="grey" />
        </visual>
        <collision>
            <origin rpy="0 0 0" xyz="0 0 0" />
            <geometry>
                <mesh filename="package://papras_description/meshes/link5.stl" scale="0.001 0.001 0.001" />
            </geometry>
        </collision>
        <inertial>
            <origin xyz="0.04029922252 -0.00098556287 -0.00018415947" rpy="0 0 0" />
            <mass value="0.37100000" />
            <inertia ixx="0.00025425095366" ixy="-0.00000045021116" ixz="-0.00000018765570" iyy="0.00024792762707" iyz="0.00000000815247" izz="0.00038245308001" />
        </inertial>
    </link>
    <gazebo reference="robot1/link6">
        <kp>1000000.0</kp>
        <kd>100.0</kd>
        <mu1>30.0</mu1>
        <mu2>30.0</mu2>
        <maxVel>1.0</maxVel>
        <minDepth>0.001</minDepth>
        <material>Gazebo/White</material>
        <selfCollide>1</selfCollide>
        <dampingFactor>0.01</dampingFactor>
    </gazebo>
    <!-- Joint 6 -->
    <joint name="robot1/joint6" type="revolute">
        <parent link="robot1/link6" />
        <child link="robot1/link7" />
        <origin rpy="0 0 0" xyz="0.06300 0.04500 0.00000" />
        <axis xyz="0 1 0" />
        <limit effort="100" lower="-1.5707963267948966" upper="1.5707963267948966" velocity="3.03687" />
        <dynamics damping="0.7" />
    </joint>
    <transmission name="robot1/tran6">
        <type>transmission_interface/SimpleTransmission</type>
        <joint name="robot1/joint6">
            <hardwareInterface>hardware_interface/PositionJointInterface</hardwareInterface>
        </joint>
        <actuator name="robot1/motor6">
            <mechanicalReduction>1</mechanicalReduction>
            <hardwareInterface>hardware_interface/EffortJointInterface</hardwareInterface>
        </actuator>
    </transmission>
    <!-- link 6 -->
    <link name="robot1/link7">
        <visual>
            <origin rpy="0 0 0" xyz="-0.034 -0.098 -0.028" />
            <geometry>
                <mesh filename="package://papras_description/meshes/link6_papras.stl" scale="0.001 0.001 0.001" />
            </geometry>
            <material name="grey" />
        </visual>
        <collision>
            <origin rpy="0 0 0" xyz="-0.034 -0.098 -0.028" />
            <geometry>
                <mesh filename="package://papras_description/meshes/link6_papras_simple.stl" scale="0.001 0.001 0.001" />
            </geometry>
        </collision>
        <inertial>
            <origin xyz="0.05226593672 -0.04440734021000001 -0.000774351999999999" rpy="0 0 0" />
            <mass value="0.38500000" />
            <inertia ixx="0.00032088715022" ixy="0.00000000348043" ixz="-0.00000000156396" iyy="0.00056261623134" iyz="-0.00000000024514" izz="0.00074173273605" />
        </inertial>
    </link>
    <gazebo reference="robot1/link7">
        <kp>1000000.0</kp>
        <kd>100.0</kd>
        <mu1>30.0</mu1>
        <mu2>30.0</mu2>
        <maxVel>1.0</maxVel>
        <minDepth>0.001</minDepth>
        <material>Gazebo/White</material>
        <selfCollide>1</selfCollide>
        <dampingFactor>0.01</dampingFactor>
    </gazebo>
    <!-- Joint 7 -->
    <joint name="robot1/joint7" type="revolute">
        <parent link="robot1/link7" />
        <child link="robot1/end_link" />
        <origin rpy="0 0 0" xyz="0.12300 -0.04500 0.00000" />
        <axis xyz="1 0 0" />
        <limit effort="100" lower="-3.141592653589793" upper="3.141592653589793" velocity="3.03687" />
        <dynamics damping="0.7" />
    </joint>
    <transmission name="robot1/tran7">
        <type>transmission_interface/SimpleTransmission</type>
        <joint name="robot1/joint7">
            <hardwareInterface>hardware_interface/PositionJointInterface</hardwareInterface>
        </joint>
        <actuator name="robot1/motor7">
            <mechanicalReduction>1</mechanicalReduction>
            <hardwareInterface>hardware_interface/EffortJointInterface</hardwareInterface>
        </actuator>
    </transmission>
    <!-- end link -->
    <link name="robot1/end_link">
        <visual>
            <origin rpy="0 0 0" xyz="0.0 0.0 0.0" />
            <geometry>
                <mesh filename="package://papras_description/meshes/end_link.stl" scale="0.001 0.001 0.001" />
            </geometry>
            <material name="grey" />
        </visual>
        <collision>
            <origin rpy="0 0 0" xyz="0.0 0.0 0.0" />
            <geometry>
                <mesh filename="package://papras_description/meshes/end_link.stl" scale="0.001 0.001 0.001" />
            </geometry>
        </collision>
        <inertial>
            <origin rpy="0 0 0" xyz="0.00337 0.00000 0.00000" />
            <mass value="0.01919" />
            <!-- <inertia ixx="1.0" ixy="0.0" ixz="0.0" iyy="1.0" iyz="0.0" izz="1.0" /> -->
            <inertia ixx="0.00000938" ixy="0.0" ixz="0.0" iyy="0.00000338" iyz="0.0" izz="0.00000635" />
        </inertial>
    </link>
    <gazebo reference="robot1/end_link">
        <kp>1000000.0</kp>
        <kd>100.0</kd>
        <mu1>30.0</mu1>
        <mu2>30.0</mu2>
        <maxVel>1.0</maxVel>
        <minDepth>0.001</minDepth>
        <material>Gazebo/White</material>
        <selfCollide>1</selfCollide>
        <dampingFactor>0.01</dampingFactor>
    </gazebo>
    <!-- gripper main fixed joint-->
    <joint name="robot1/end_link_fixed" type="fixed">
        <parent link="robot1/end_link" />
        <child link="robot1/gripper_main_link" />
        <origin rpy="0 -1.5707963267948966 3.141592653589793" xyz="0.006 0.0 0.0" />
    </joint>
    <!-- gripper main link -->
    <link name="robot1/gripper_main_link">
        <collision>
            <origin rpy="0 0 0" xyz="0 0 0" />
            <geometry>
                <mesh filename="package://papras_description/meshes/rh_p12_rn_base.stl" scale="0.001 0.001 0.001" />
            </geometry>
        </collision>
        <visual>
            <origin rpy="0 0 0" xyz="0 0 0" />
            <geometry>
                <mesh filename="package://papras_description/meshes/rh_p12_rn_base.stl" scale="0.001 0.001 0.001" />
            </geometry>
            <material name="grey" />
        </visual>
        <inertial>
            <origin rpy="0 0 0" xyz="0.000 0.000 0.032" />
            <mass value="0.236" />
            <!--<inertia ixx="0.00017" ixy="0.0" ixz="0.0" iyy="0.00011" iyz="0.0" izz="0.00017" />-->
            <inertia ixx="1.0" ixy="0.0" ixz="0.0" iyy="1.0" iyz="0.0" izz="1.0" />
        </inertial>
    </link>
    <gazebo reference="robot1/gripper_main_link">
        <kp>1000000.0</kp>
        <kd>100.0</kd>
        <mu1>30.0</mu1>
        <mu2>30.0</mu2>
        <maxVel>1.0</maxVel>
        <minDepth>0.001</minDepth>
        <material>Gazebo/White</material>
        <selfCollide>1</selfCollide>
        <dampingFactor>0.01</dampingFactor>
    </gazebo>
    <!-- gripper joint -->
    <joint name="robot1/gripper" type="revolute">
        <parent link="robot1/gripper_main_link" />
        <child link="robot1/gripper_link" />
        <origin rpy="0 0 0" xyz="0.0 0.008 0.048" />
        <axis xyz="1 0 0" />
        <limit effort="1000" lower="0.0" upper="1.1" velocity="6.5" />
        <dynamics damping="0.7" />
    </joint>
    <transmission name="robot1/trangripper">
        <type>transmission_interface/SimpleTransmission</type>
        <joint name="robot1/gripper">
            <hardwareInterface>hardware_interface/EffortJointInterface</hardwareInterface>
        </joint>
        <actuator name="robot1/motorgripper">
            <mechanicalReduction>1</mechanicalReduction>
            <hardwareInterface>hardware_interface/EffortJointInterface</hardwareInterface>
        </actuator>
    </transmission>
    <!-- gripper link -->
    <link name="robot1/gripper_link">
        <collision>
            <origin rpy="0 0 0" xyz="0 0 0" />
            <geometry>
                <mesh filename="package://papras_description/meshes/rh_p12_rn_r1.stl" scale="0.001 0.001 0.001" />
            </geometry>
        </collision>
        <visual>
            <origin rpy="0 0 0" xyz="0 0 0" />
            <geometry>
                <mesh filename="package://papras_description/meshes/rh_p12_rn_r1.stl" scale="0.001 0.001 0.001" />
            </geometry>
            <material name="grey" />
        </visual>
        <inertial>
            <origin rpy="0 0 0" xyz="0.000 0.034 0.004" />
            <mass value="0.068" />
            <!--<inertia ixx="0.00004" ixy="0.0" ixz="0.0" iyy="0.00002" iyz="-0.00001" izz="0.00002" />-->
            <inertia ixx="1.0" ixy="0.0" ixz="0.0" iyy="1.0" iyz="0.0" izz="1.0" />
        </inertial>
    </link>
    <gazebo reference="robot1/gripper_link">
        <kp>1000000.0</kp>
        <kd>100.0</kd>
        <mu1>30.0</mu1>
        <mu2>30.0</mu2>
        <maxVel>1.0</maxVel>
        <minDepth>0.001</minDepth>
        <material>Gazebo/White</material>
        <selfCollide>1</selfCollide>
        <dampingFactor>0.01</dampingFactor>
    </gazebo>
    <joint name="robot1/gripper_r2" type="revolute">
        <parent link="robot1/gripper_link" />
        <child link="robot1/gripper_link_r2" />
        <origin rpy="0 0 0" xyz="0.0 0.0493634 0.0285" />
        <axis xyz="-1 0 0" />
        <limit effort="1000" lower="0.0" upper="1.0" velocity="6.5" />
        <dynamics damping="0.7" />
        <mimic joint="robot1/gripper" multiplier="0.9090909090909091" />
    </joint>
    <transmission name="robot1/trangripper_r2">
        <type>transmission_interface/SimpleTransmission</type>
        <joint name="robot1/gripper_r2">
            <hardwareInterface>hardware_interface/EffortJointInterface</hardwareInterface>
        </joint>
        <actuator name="robot1/motorgripper_r2">
            <mechanicalReduction>1</mechanicalReduction>
            <hardwareInterface>hardware_interface/EffortJointInterface</hardwareInterface>
        </actuator>
    </transmission>
    <!-- rh_p12_rn_r2 -->
    <link name="robot1/gripper_link_r2">
        <collision>
            <origin rpy="0 0 0" xyz="0 0 0" />
            <geometry>
                <mesh filename="package://papras_description/meshes/rh_p12_rn_r2.stl" scale="0.001 0.001 0.001" />
            </geometry>
        </collision>
        <visual>
            <origin rpy="0 0 0" xyz="0 0 0" />
            <geometry>
                <mesh filename="package://papras_description/meshes/rh_p12_rn_r2.stl" scale="0.001 0.001 0.001" />
            </geometry>
            <material name="grey" />
        </visual>
        <inertial>
            <origin rpy="0 0 0" xyz="0.000 0.006 0.011" />
            <mass value="0.022" />
            <!--<inertia ixx="0.0" ixy="0.0" ixz="0.0" iyy="0.00001" iyz="0.0" izz="0.0" />-->
            <inertia ixx="1.0" ixy="0.0" ixz="0.0" iyy="1.0" iyz="0.0" izz="1.0" />
        </inertial>
    </link>
    <gazebo reference="robot1/gripper_link_r2">
        <kp>1000000.0</kp>
        <kd>100.0</kd>
        <mu1>30.0</mu1>
        <mu2>30.0</mu2>
        <maxVel>1.0</maxVel>
        <minDepth>0.001</minDepth>
        <material>Gazebo/White</material>
        <selfCollide>1</selfCollide>
        <dampingFactor>0.01</dampingFactor>
    </gazebo>
    <!-- Left Joint 1 -->
    <joint name="robot1/gripper_l1" type="revolute">
        <parent link="robot1/gripper_main_link" />
        <child link="robot1/gripper_link_l1" />
        <origin rpy="0 0 0" xyz="0.0 -0.008 0.048" />
        <axis xyz="-1 0 0" />
        <limit effort="1000" lower="0.0" upper="1.1" velocity="6.5" />
        <dynamics damping="0.7" />
        <mimic joint="robot1/gripper" multiplier="1.0" />
    </joint>
    <transmission name="robot1/trangripper_l1">
        <type>transmission_interface/SimpleTransmission</type>
        <joint name="robot1/gripper_l1">
            <hardwareInterface>hardware_interface/EffortJointInterface</hardwareInterface>
        </joint>
        <actuator name="robot1/motorgripper_l1">
            <mechanicalReduction>1</mechanicalReduction>
            <hardwareInterface>hardware_interface/EffortJointInterface</hardwareInterface>
        </actuator>
    </transmission>
    <!-- rh_p12_rn_l1 -->
    <link name="robot1/gripper_link_l1">
        <collision>
            <origin rpy="0 0 0" xyz="0 0 0" />
            <geometry>
                <mesh filename="package://papras_description/meshes/rh_p12_rn_l1.stl" scale="0.001 0.001 0.001" />
            </geometry>
        </collision>
        <visual>
            <origin rpy="0 0 0" xyz="0 0 0" />
            <geometry>
                <mesh filename="package://papras_description/meshes/rh_p12_rn_l1.stl" scale="0.001 0.001 0.001" />
            </geometry>
            <material name="grey" />
        </visual>
        <inertial>
            <origin rpy="0 0 0" xyz="0.000 -0.034 0.004" />
            <mass value="0.068" />
            <!--<inertia ixx="0.00004" ixy="0.0" ixz="0.0" iyy="0.00002" iyz="0.00001" izz="0.00002" />-->
            <inertia ixx="1.0" ixy="0.0" ixz="0.0" iyy="1.0" iyz="0.0" izz="1.0" />
        </inertial>
    </link>
    <gazebo reference="robot1/gripper_link_l1">
        <kp>1000000.0</kp>
        <kd>100.0</kd>
        <mu1>30.0</mu1>
        <mu2>30.0</mu2>
        <maxVel>1.0</maxVel>
        <minDepth>0.001</minDepth>
        <material>Gazebo/White</material>
        <selfCollide>1</selfCollide>
        <dampingFactor>0.01</dampingFactor>
    </gazebo>
    <!-- Left Joint 2 -->
    <joint name="robot1/gripper_l2" type="revolute">
        <parent link="robot1/gripper_link_l1" />
        <child link="robot1/gripper_link_l2" />
        <origin rpy="0 0 0" xyz="0.0 -0.0493634 0.0285" />
        <axis xyz="1 0 0" />
        <limit effort="1000" lower="0.0" upper="1.0" velocity="6.5" />
        <dynamics damping="0.7" />
        <mimic joint="robot1/gripper" multiplier="0.9090909090909091" />
    </joint>
    <transmission name="robot1/trangripper_l2">
        <type>transmission_interface/SimpleTransmission</type>
        <joint name="robot1/gripper_l2">
            <hardwareInterface>hardware_interface/EffortJointInterface</hardwareInterface>
        </joint>
        <actuator name="robot1/motorgripper_l2">
            <mechanicalReduction>1</mechanicalReduction>
            <hardwareInterface>hardware_interface/EffortJointInterface</hardwareInterface>
        </actuator>
    </transmission>
    <link name="robot1/gripper_link_l2">
        <collision>
            <origin rpy="0 0 0" xyz="0 0 0" />
            <geometry>
                <mesh filename="package://papras_description/meshes/rh_p12_rn_l2.stl" scale="0.001 0.001 0.001" />
            </geometry>
        </collision>
        <visual>
            <origin rpy="0 0 0" xyz="0 0 0" />
            <geometry>
                <mesh filename="package://papras_description/meshes/rh_p12_rn_l2.stl" scale="0.001 0.001 0.001" />
            </geometry>
            <material name="grey" />
        </visual>
        <inertial>
            <origin rpy="0 0 0" xyz="0.000 -0.006 0.011" />
            <mass value="0.022" />
            <!--<inertia ixx="0.0" ixy="0.0" ixz="0.0" iyy="0.00001" iyz="0.0" izz="0.0" />-->
            <inertia ixx="1.0" ixy="0.0" ixz="0.0" iyy="1.0" iyz="0.0" izz="1.0" />
        </inertial>
    </link>
    <!-- gripper main fixed joint-->
    <joint name="robot1/end_effector_joint" type="fixed">
        <parent link="robot1/gripper_main_link" />
        <child link="robot1/end_effector_link" />
        <origin rpy="3.141592653589793 -1.5707963267948966 0" xyz="0.0 0.0 0.135" />
    </joint>
    <!-- End Effector -->
    <link name="robot1/end_effector_link">
        <visual>
            <origin rpy="0 0 0" xyz="0.0 0.0 0.0" />
            <geometry>
                <box size="0.01 0.01 0.01" />
            </geometry>
            <material name="red" />
        </visual>
        <!-- <collision>
          <origin xyz="0.0 0.0 0.0" rpy="0 0 0" />
          <geometry>
            <box size = "0.01 0.01 0.01"/>
          </geometry>
          <material name="red"/>
        </collision> -->
        <inertial>
            <origin rpy="0 0 0" xyz="0.0 0.0 0.0" />
            <mass value="0.001" />
            <inertia ixx="1.0" ixy="0.0" ixz="0.0" iyy="1.0" iyz="0.0" izz="1.0" />
        </inertial>
    </link>
    <gazebo reference="robot1/end_effector_link">
        <material>Gazebo/Red</material>
    </gazebo>
    <!-- camera link fixed joint -->
    <joint name="robot1/camera_fixed_joint" type="fixed">
        <parent link="robot1/gripper_main_link" />
        <child link="robot1/camera_mount" />
        <origin rpy="0 0 1.5707963267948966" xyz="0.04452 -0.0167 0.049" />
    </joint>
    <!-- <origin xyz="0.0592 0.0167 0.04452" rpy="${-0.5*pi} 0 ${-0.5*pi}" /> -->
    <!-- Camera Mount -->
    <link name="robot1/camera_mount">
        <visual>
            <origin rpy="1.5707963267948966 -1.5707963267948966 0" xyz="0 0 0" />
            <geometry>
                <mesh filename="package://papras_description/meshes/camera_mount.stl" />
            </geometry>
            <material name="grey" />
        </visual>
        <collision>
            <origin rpy="1.5707963267948966 -1.5707963267948966 0" xyz="0 0 0" />
            <geometry>
                <mesh filename="package://papras_description/meshes/camera_mount_simple.stl" />
            </geometry>
        </collision>
        <inertial>
            <origin rpy="1.5707963267948966 -1.5707963267948966 0" xyz="0 0 0" />
            <mass value="0.088" />
            <inertia ixx="1.0" ixy="0.0" ixz="0.0" iyy="1.0" iyz="0.0" izz="1.0" />
        </inertial>
    </link>
    <gazebo reference="robot1/camera_mount">
        <kp>1000000.0</kp>
        <kd>100.0</kd>
        <mu1>30.0</mu1>
        <mu2>30.0</mu2>
        <maxVel>1.0</maxVel>
        <minDepth>0.001</minDepth>
        <material>Gazebo/White</material>
        <selfCollide>1</selfCollide>
        <dampingFactor>0.01</dampingFactor>
    </gazebo>
    <joint name="robot1/camera_mount_link" type="fixed">
        <parent link="robot1/camera_mount" />
        <child link="robot1/camera_link" />
        <origin rpy="0 0 0" xyz="-0.015 0 0" />
    </joint>
    <link name="robot1/camera_link" />
    <joint name="robot1/camera_fixed_plugin_joint" type="fixed">
        <parent link="robot1/camera_link" />
        <child link="robot1/camera_plugin_link" />
        <origin rpy="1.5707963267948966 -1.5707963267948966 0" xyz="0 0 0" />
    </joint>
    <link name="robot1/camera_plugin_link" />
    <gazebo reference="robot1/camera_plugin_link">
        <kp>1000000.0</kp>
        <kd>100.0</kd>
        <mu1>30.0</mu1>
        <mu2>30.0</mu2>
        <maxVel>1.0</maxVel>
        <minDepth>0.001</minDepth>
        <material>Gazebo/White</material>
        <selfCollide>1</selfCollide>
        <dampingFactor>0.01</dampingFactor>
    </gazebo>
</robot>

