<?xml version="1.0" encoding="utf-8" ?>
<!-- =================================================================================== -->
<!-- |    This document was autogenerated by xacro from /home/kazukishin/catkin_kazukis2/src/PAPRAS/open_manipulator_p/open_manipulator_p_description/urdf/papras_group_moveit.urdf.xacro | -->
<!-- |    EDITING THIS FILE BY HAND IS NOT RECOMMENDED                                 | -->
<!-- =================================================================================== -->
<robot name="open_manipulator_p">
    <material name="black">
        <color rgba="0.0 0.0 0.0 1.0" />
    </material>
    <material name="blue">
        <color rgba="0.0 0.0 0.8 1.0" />
    </material>
    <material name="green">
        <color rgba="0.0 0.8 0.0 1.0" />
    </material>
    <material name="grey">
        <color rgba="0.5 0.5 0.5 1.0" />
    </material>
    <material name="orange">
        <color rgba="1.0 0.423529411765 0.0392156862745 1.0" />
    </material>
    <material name="brown">
        <color rgba="0.870588235294 0.811764705882 0.764705882353 1.0" />
    </material>
    <material name="red">
        <color rgba="0.8 0.0 0.0 1.0" />
    </material>
    <material name="white">
        <color rgba="1.0 1.0 1.0 1.0" />
    </material>
    <!-- World -->
    <gazebo reference="world" />
    <gazebo reference="link1">
        <kp>1000000.0</kp>
        <kd>100.0</kd>
        <mu1>30.0</mu1>
        <mu2>30.0</mu2>
        <maxVel>1.0</maxVel>
        <minDepth>0.001</minDepth>
        <material>Gazebo/DarkGrey</material>
    </gazebo>
    <gazebo reference="link2">
        <kp>1000000.0</kp>
        <kd>100.0</kd>
        <mu1>30.0</mu1>
        <mu2>30.0</mu2>
        <maxVel>1.0</maxVel>
        <minDepth>0.001</minDepth>
        <material>Gazebo/DarkGrey</material>
    </gazebo>
    <gazebo reference="link3">
        <kp>1000000.0</kp>
        <kd>100.0</kd>
        <mu1>30.0</mu1>
        <mu2>30.0</mu2>
        <maxVel>1.0</maxVel>
        <minDepth>0.001</minDepth>
        <material>Gazebo/DarkGrey</material>
    </gazebo>
    <gazebo reference="link4">
        <kp>1000000.0</kp>
        <kd>100.0</kd>
        <mu1>30.0</mu1>
        <mu2>30.0</mu2>
        <maxVel>1.0</maxVel>
        <minDepth>0.001</minDepth>
        <material>Gazebo/DarkGrey</material>
    </gazebo>
    <gazebo reference="link5">
        <kp>1000000.0</kp>
        <kd>100.0</kd>
        <mu1>30.0</mu1>
        <mu2>30.0</mu2>
        <maxVel>1.0</maxVel>
        <minDepth>0.001</minDepth>
        <material>Gazebo/DarkGrey</material>
    </gazebo>
    <gazebo reference="link6">
        <kp>1000000.0</kp>
        <kd>100.0</kd>
        <mu1>30.0</mu1>
        <mu2>30.0</mu2>
        <maxVel>1.0</maxVel>
        <minDepth>0.001</minDepth>
        <material>Gazebo/DarkGrey</material>
    </gazebo>
    <gazebo reference="end_link">
        <kp>1000000.0</kp>
        <kd>100.0</kd>
        <mu1>30.0</mu1>
        <mu2>30.0</mu2>
        <maxVel>1.0</maxVel>
        <minDepth>0.001</minDepth>
        <material>Gazebo/DarkGrey</material>
    </gazebo>
    <!-- ros_control plugin -->
    <gazebo>
        <plugin filename="libgazebo_ros_control.so" name="gazebo_ros_control">
            <robotSimType>gazebo_ros_control/DefaultRobotHWSim</robotSimType>
        </plugin>
    </gazebo>
    <transmission name="robot1/tran1">
        <type>transmission_interface/SimpleTransmission</type>
        <joint name="robot1/joint1">
            <hardwareInterface>hardware_interface/PositionJointInterface</hardwareInterface>
        </joint>
        <actuator name="robot1/motor1">
            <mechanicalReduction>1</mechanicalReduction>
        </actuator>
    </transmission>
    <transmission name="robot2/tran1">
        <type>transmission_interface/SimpleTransmission</type>
        <joint name="robot2/joint1">
            <hardwareInterface>hardware_interface/PositionJointInterface</hardwareInterface>
        </joint>
        <actuator name="robot2/motor1">
            <mechanicalReduction>1</mechanicalReduction>
        </actuator>
    </transmission>
    <transmission name="robot3/tran1">
        <type>transmission_interface/SimpleTransmission</type>
        <joint name="robot3/joint1">
            <hardwareInterface>hardware_interface/PositionJointInterface</hardwareInterface>
        </joint>
        <actuator name="robot3/motor1">
            <mechanicalReduction>1</mechanicalReduction>
        </actuator>
    </transmission>
    <transmission name="robot1/tran2">
        <type>transmission_interface/SimpleTransmission</type>
        <joint name="robot1/joint2">
            <hardwareInterface>hardware_interface/PositionJointInterface</hardwareInterface>
        </joint>
        <actuator name="robot1/motor2">
            <mechanicalReduction>1</mechanicalReduction>
        </actuator>
    </transmission>
    <transmission name="robot2/tran2">
        <type>transmission_interface/SimpleTransmission</type>
        <joint name="robot2/joint2">
            <hardwareInterface>hardware_interface/PositionJointInterface</hardwareInterface>
        </joint>
        <actuator name="robot2/motor2">
            <mechanicalReduction>1</mechanicalReduction>
        </actuator>
    </transmission>
    <transmission name="robot3/tran2">
        <type>transmission_interface/SimpleTransmission</type>
        <joint name="robot3/joint2">
            <hardwareInterface>hardware_interface/PositionJointInterface</hardwareInterface>
        </joint>
        <actuator name="robot3/motor2">
            <mechanicalReduction>1</mechanicalReduction>
        </actuator>
    </transmission>
    <transmission name="robot1/tran3">
        <type>transmission_interface/SimpleTransmission</type>
        <joint name="robot1/joint3">
            <hardwareInterface>hardware_interface/PositionJointInterface</hardwareInterface>
        </joint>
        <actuator name="robot1/motor3">
            <mechanicalReduction>1</mechanicalReduction>
        </actuator>
    </transmission>
    <transmission name="robot2/tran3">
        <type>transmission_interface/SimpleTransmission</type>
        <joint name="robot2/joint3">
            <hardwareInterface>hardware_interface/PositionJointInterface</hardwareInterface>
        </joint>
        <actuator name="robot2/motor3">
            <mechanicalReduction>1</mechanicalReduction>
        </actuator>
    </transmission>
    <transmission name="robot3/tran3">
        <type>transmission_interface/SimpleTransmission</type>
        <joint name="robot3/joint3">
            <hardwareInterface>hardware_interface/PositionJointInterface</hardwareInterface>
        </joint>
        <actuator name="robot3/motor3">
            <mechanicalReduction>1</mechanicalReduction>
        </actuator>
    </transmission>
    <transmission name="robot1/tran4">
        <type>transmission_interface/SimpleTransmission</type>
        <joint name="robot1/joint4">
            <hardwareInterface>hardware_interface/PositionJointInterface</hardwareInterface>
        </joint>
        <actuator name="robot1/motor4">
            <mechanicalReduction>1</mechanicalReduction>
        </actuator>
    </transmission>
    <transmission name="robot2/tran4">
        <type>transmission_interface/SimpleTransmission</type>
        <joint name="robot2/joint4">
            <hardwareInterface>hardware_interface/PositionJointInterface</hardwareInterface>
        </joint>
        <actuator name="robot2/motor4">
            <mechanicalReduction>1</mechanicalReduction>
        </actuator>
    </transmission>
    <transmission name="robot3/tran4">
        <type>transmission_interface/SimpleTransmission</type>
        <joint name="robot3/joint4">
            <hardwareInterface>hardware_interface/PositionJointInterface</hardwareInterface>
        </joint>
        <actuator name="robot3/motor4">
            <mechanicalReduction>1</mechanicalReduction>
        </actuator>
    </transmission>
    <transmission name="robot1/tran5">
        <type>transmission_interface/SimpleTransmission</type>
        <joint name="robot1/joint5">
            <hardwareInterface>hardware_interface/PositionJointInterface</hardwareInterface>
        </joint>
        <actuator name="robot1/motor5">
            <mechanicalReduction>1</mechanicalReduction>
        </actuator>
    </transmission>
    <transmission name="robot2/tran5">
        <type>transmission_interface/SimpleTransmission</type>
        <joint name="robot2/joint5">
            <hardwareInterface>hardware_interface/PositionJointInterface</hardwareInterface>
        </joint>
        <actuator name="robot2/motor5">
            <mechanicalReduction>1</mechanicalReduction>
        </actuator>
    </transmission>
    <transmission name="robot3/tran5">
        <type>transmission_interface/SimpleTransmission</type>
        <joint name="robot3/joint5">
            <hardwareInterface>hardware_interface/PositionJointInterface</hardwareInterface>
        </joint>
        <actuator name="robot3/motor5">
            <mechanicalReduction>1</mechanicalReduction>
        </actuator>
    </transmission>
    <transmission name="robot1/tran6">
        <type>transmission_interface/SimpleTransmission</type>
        <joint name="robot1/joint6">
            <hardwareInterface>hardware_interface/PositionJointInterface</hardwareInterface>
        </joint>
        <actuator name="robot1/motor6">
            <mechanicalReduction>1</mechanicalReduction>
        </actuator>
    </transmission>
    <transmission name="robot2/tran6">
        <type>transmission_interface/SimpleTransmission</type>
        <joint name="robot2/joint6">
            <hardwareInterface>hardware_interface/PositionJointInterface</hardwareInterface>
        </joint>
        <actuator name="robot2/motor6">
            <mechanicalReduction>1</mechanicalReduction>
        </actuator>
    </transmission>
    <transmission name="robot3/tran6">
        <type>transmission_interface/SimpleTransmission</type>
        <joint name="robot3/joint6">
            <hardwareInterface>hardware_interface/PositionJointInterface</hardwareInterface>
        </joint>
        <actuator name="robot3/motor6">
            <mechanicalReduction>1</mechanicalReduction>
        </actuator>
    </transmission>
    <!-- World -->
    <link name="world" />
    <joint name="robot1/world_fixed" type="fixed">
        <parent link="world" />
        <child link="robot1/link1" />
        <origin rpy="0 0 1.57" xyz="-0.3 0.1 0.853625" />
    </joint>
    <!-- link 1 -->
    <link name="robot1/link1">
        <visual>
            <origin rpy="0 0 0" xyz="0 0 0" />
            <geometry>
                <mesh filename="package://open_manipulator_p_description/meshes/link1.stl" scale="0.001 0.001 0.001" />
            </geometry>
            <material name="grey" />
        </visual>
        <collision>
            <origin rpy="0 0 0" xyz="0 0 0" />
            <geometry>
                <mesh filename="package://open_manipulator_p_description/meshes/link1.stl" scale="0.001 0.001 0.001" />
            </geometry>
        </collision>
        
<inertial>
            <origin rpy="0 0 0" xyz="0.00023 0.00000 0.06223" />
            <mass value="0.85644" />
            <inertia ixx="1.0" ixy="0.0" ixz="0.0" iyy="1.0" iyz="0.0" izz="1.0" />
            <!--<inertia ixx="0.00121064" ixy="0.0" ixz="0.00001100" iyy="0.00120886" iyz="0.0" izz="0.00038103" />-->
        </inertial>

    </link>
    <!-- Joint 1 -->
    <joint name="robot1/joint1" type="revolute">
        <parent link="robot1/link1" />
        <child link="robot1/link2" />
        <origin rpy="0 0 0" xyz="0.0 0.0 0.126" />
        <axis xyz="0 0 1" />
        <limit effort="1000" lower="-1.57079632679" upper="1.57079632679" velocity="6.5" />
        <dynamics damping="0.7" />
    </joint>
    <!-- link 2 -->
    <link name="robot1/link2">
        <visual>
            <origin rpy="0 0 0" xyz="0 0 0" />
            <geometry>
                <mesh filename="package://open_manipulator_p_description/meshes/link2.stl" scale="0.001 0.001 0.001" />
            </geometry>
            <material name="grey" />
        </visual>
        <collision>
            <origin rpy="0 0 0" xyz="0 0 0" />
            <geometry>
                <mesh filename="package://open_manipulator_p_description/meshes/link2.stl" scale="0.001 0.001 0.001" />
            </geometry>
        </collision>
        
<inertial>
            <origin rpy="0 0 0" xyz="0.00000 0.00080 0.03183" />
            <!--<origin xyz="0.00000 -0.06820 -0.00117" rpy="0 0 0"/>-->
            <mass value="0.94658" />
            <inertia ixx="1.0" ixy="0.0" ixz="0.0" iyy="1.0" iyz="0.0" izz="1.0" />
            <!--<inertia ixx="0.00152547" ixy="0.0" ixz="0.0" iyy="0.00045954" iyz="-0.00001086" izz="0.00151740" />-->
        </inertial>

    </link>
    <!-- Joint 2 -->
    <joint name="robot1/joint2" type="revolute">
        <parent link="robot1/link2" />
        <child link="robot1/link3" />
        <origin rpy="0 0 0" xyz="0.0 0.069 0.033" />
        <axis xyz="0 1 0" />
        <limit effort="1000" lower="-1.57079632679" upper="1.57079632679" velocity="6.5" />
        <dynamics damping="0.7" />
    </joint>
    <!-- link 3 -->
    <link name="robot1/link3">
        <visual>
            <origin xyz="0.067 0.008 -0.019" rpy="0 0 3.14"/>
            <geometry>
                <mesh filename="package://open_manipulator_p_description/meshes/link3_papras.stl" scale="0.001 0.001 0.001"/>
            </geometry>
            <material name="grey" />
        </visual>
        <collision>
            <origin xyz="0.067 0.008 -0.019" rpy="0 0 3.14"/>
            <geometry>
                <mesh filename="package://open_manipulator_p_description/meshes/link3_papras.stl" scale="0.001 0.001 0.001"/>
            </geometry>
        </collision>
        
<inertial>
            <origin rpy="0 0 0" xyz="0.01768 -0.06881 0.20524" />
            <!--<origin xyz="-0.01232 -0.05731 -0.05876" rpy="0 0 0"/>-->
            <mass value="1.30260" />
            <inertia ixx="1.0" ixy="0.0" ixz="0.0" iyy="1.0" iyz="0.0" izz="1.0" />
            <!--<inertia ixx="0.01111021" ixy="0.00001331" ixz="-0.00134208" iyy="0.01046642" iyz="0.00016235" izz="0.00202081" />-->
        </inertial>

    </link>
    <!-- Joint 3 -->
    <joint name="robot1/joint3" type="revolute">
        <parent link="robot1/link3" />
        <child link="robot1/link4" />
        <origin rpy="0 0 0" xyz="0.03000 -0.01150 0.26400" />
        <axis xyz="0 1 0" />
        <limit effort="1000" lower="-1.57079632679" upper="1.57079632679" velocity="6.5" />
        <dynamics damping="0.7" />
    </joint>
    <!-- link 4 -->
    <link name="robot1/link4">
        <visual>
            <origin xyz="0.227 0.0085 -0.024" rpy="0 0 3.14"/>
            <geometry>
                <mesh filename="package://open_manipulator_p_description/meshes/link4_papras.stl" scale="0.001 0.001 0.001"/>
            </geometry>
            <material name="grey" />
        </visual>
        <collision>
            <origin xyz="0.227 0.0085 -0.024" rpy="0 0 3.14"/>
            <geometry>
                <mesh filename="package://open_manipulator_p_description/meshes/link4_papras.stl" scale="0.001 0.001 0.001"/>
            </geometry>
        </collision>
        
<inertial>
            <origin rpy="0 0 0" xyz="0.12475 -0.05716 0.02979" />
            <!--<origin xyz="-0.07025 0.00034 -0.00021" rpy="0 0 0"/>-->
            <mass value="1.15977" />
            <inertia ixx="1.0" ixy="0.0" ixz="0.0" iyy="1.0" iyz="0.0" izz="1.0" />
            <!--<inertia ixx="0.00096726" ixy="0.00004383" ixz="-0.00002771" iyy="0.00318801" iyz="0.00000627" izz="0.00341484" />-->
        </inertial>

    </link>
    <!-- Joint 4 -->
    <joint name="robot1/joint4" type="revolute">
        <parent link="robot1/link4" />
        <child link="robot1/link5" />
        <origin rpy="0 0 0" xyz="0.19500 -0.05750 0.03000" />
        <axis xyz="1 0 0" />
        <limit effort="1000" lower="-1.57079632679" upper="1.57079632679" velocity="6.5" />
        <dynamics damping="0.7" />
    </joint>
    <!-- link 5 -->
    <link name="robot1/link5">
        <visual>
            <origin rpy="0 0 0" xyz="0 0 0" />
            <geometry>
                <mesh filename="package://open_manipulator_p_description/meshes/link5.stl" scale="0.001 0.001 0.001" />
            </geometry>
            <material name="grey" />
        </visual>
        <collision>
            <origin rpy="0 0 0" xyz="0 0 0" />
            <geometry>
                <mesh filename="package://open_manipulator_p_description/meshes/link5.stl" scale="0.001 0.001 0.001" />
            </geometry>
        </collision>
        
<inertial>
            <origin rpy="0 0 0" xyz="0.05642 -0.00217 0.00002" />
            <!--<origin xyz="-0.00658 -0.04717 0.00002" rpy="0 0 0"/>-->
            <mass value="0.44688" />
            <inertia ixx="1.0" ixy="0.0" ixz="0.0" iyy="1.0" iyz="0.0" izz="1.0" />
            <!--<inertia ixx="0.00030285" ixy="0.00000761" ixz="0.00000031" iyy="0.00022339" iyz="-0.00000001" izz="0.00039766" />-->
        </inertial>

    </link>
    <!-- Joint 5 -->
    <joint name="robot1/joint5" type="revolute">
        <parent link="robot1/link5" />
        <child link="robot1/link6" />
        <origin rpy="0 0 0" xyz="0.06300 0.04500 0.00000" />
        <axis xyz="0 1 0" />
        <limit effort="1000" lower="-1.57079632679" upper="1.57079632679" velocity="6.5" />
        <dynamics damping="0.7" />
    </joint>
    <!-- link 6 -->
    <link name="robot1/link6">
        <visual>
            <origin xyz="-0.034 -0.098 -0.028" rpy="0 0 0"/>
            <geometry>
                <mesh filename="package://open_manipulator_p_description/meshes/link6_papras.stl" scale="0.001 0.001 0.001"/>
            </geometry>
            <material name="grey" />
        </visual>
        <collision>
            <origin xyz="-0.034 -0.098 -0.028" rpy="0 0 0"/>
            <geometry>
                <mesh filename="package://open_manipulator_p_description/meshes/link6_papras.stl" scale="0.001 0.001 0.001"/>
            </geometry>
        </collision>
        
<inertial>
            <origin rpy="0 0 0" xyz="0.06831 -0.04457 0.00000" />
            <!--<origin xyz="-0.05469 0.00043 0.00000" rpy="0 0 0"/>-->
            <mass value="0.43273" />
            <inertia ixx="1.0" ixy="0.0" ixz="0.0" iyy="1.0" iyz="0.0" izz="1.0" />
            <!--<inertia ixx="0.00021512" ixy="0.00001009" ixz="0.00000000" iyy="0.00042827" iyz="0.00000000" izz="0.00051436" />-->
        </inertial>

    </link>
    <!-- Joint 6 -->
    <joint name="robot1/joint6" type="revolute">
        <parent link="robot1/link6" />
        <child link="robot1/end_link" />
        <origin rpy="0 0 0" xyz="0.12300 -0.04500 0.00000" />
        <axis xyz="1 0 0" />
        <limit effort="1000" lower="-1.57079632679" upper="1.57079632679" velocity="6.5" />
        <dynamics damping="0.7" />
    </joint>
    <!-- end link -->
    <link name="robot1/end_link">
        <visual>
            <origin rpy="0 0 0" xyz="0.0 0.0 0.0" />
            <geometry>
                <mesh filename="package://open_manipulator_p_description/meshes/end_link.stl" scale="0.001 0.001 0.001" />
            </geometry>
            <material name="grey" />
        </visual>
        <collision>
            <origin rpy="0 0 0" xyz="0.0 0.0 0.0" />
            <geometry>
                <mesh filename="package://open_manipulator_p_description/meshes/end_link.stl" scale="0.001 0.001 0.001" />
            </geometry>
        </collision>
        
<inertial>
            <origin rpy="0 0 0" xyz="0.00337 0.00000 0.00000" />
            <mass value="0.01919" />
            <inertia ixx="1.0" ixy="0.0" ixz="0.0" iyy="1.0" iyz="0.0" izz="1.0" />
            <!--<inertia ixx="0.00000938" ixy="0.0" ixz="0.0" iyy="0.00000338" iyz="0.0" izz="0.00000635" />-->
        </inertial>

    </link>
    <joint name="robot2/world_fixed" type="fixed">
        <parent link="world" />
        <child link="robot2/link1" />
        <origin rpy="0 0 1.57" xyz="-0.3 -0.5 0.853625" />
    </joint>
    <!-- link 1 -->
    <link name="robot2/link1">
        <visual>
            <origin rpy="0 0 0" xyz="0 0 0" />
            <geometry>
                <mesh filename="package://open_manipulator_p_description/meshes/link1.stl" scale="0.001 0.001 0.001" />
            </geometry>
            <material name="grey" />
        </visual>
        <collision>
            <origin rpy="0 0 0" xyz="0 0 0" />
            <geometry>
                <mesh filename="package://open_manipulator_p_description/meshes/link1.stl" scale="0.001 0.001 0.001" />
            </geometry>
        </collision>
        
<inertial>
            <origin rpy="0 0 0" xyz="0.00023 0.00000 0.06223" />
            <mass value="0.85644" />
            <inertia ixx="1.0" ixy="0.0" ixz="0.0" iyy="1.0" iyz="0.0" izz="1.0" />
            <!--<inertia ixx="0.00121064" ixy="0.0" ixz="0.00001100" iyy="0.00120886" iyz="0.0" izz="0.00038103" />-->
        </inertial>

    </link>
    <!-- Joint 1 -->
    <joint name="robot2/joint1" type="revolute">
        <parent link="robot2/link1" />
        <child link="robot2/link2" />
        <origin rpy="0 0 0" xyz="0.0 0.0 0.126" />
        <axis xyz="0 0 1" />
        <limit effort="1000" lower="-1.57079632679" upper="1.57079632679" velocity="6.5" />
        <dynamics damping="0.7" />
    </joint>
    <!-- link 2 -->
    <link name="robot2/link2">
        <visual>
            <origin rpy="0 0 0" xyz="0 0 0" />
            <geometry>
                <mesh filename="package://open_manipulator_p_description/meshes/link2.stl" scale="0.001 0.001 0.001" />
            </geometry>
            <material name="grey" />
        </visual>
        <collision>
            <origin rpy="0 0 0" xyz="0 0 0" />
            <geometry>
                <mesh filename="package://open_manipulator_p_description/meshes/link2.stl" scale="0.001 0.001 0.001" />
            </geometry>
        </collision>
        
<inertial>
            <origin rpy="0 0 0" xyz="0.00000 0.00080 0.03183" />
            <!--<origin xyz="0.00000 -0.06820 -0.00117" rpy="0 0 0"/>-->
            <mass value="0.94658" />
            <inertia ixx="1.0" ixy="0.0" ixz="0.0" iyy="1.0" iyz="0.0" izz="1.0" />
            <!--<inertia ixx="0.00152547" ixy="0.0" ixz="0.0" iyy="0.00045954" iyz="-0.00001086" izz="0.00151740" />-->
        </inertial>

    </link>
    <!-- Joint 2 -->
    <joint name="robot2/joint2" type="revolute">
        <parent link="robot2/link2" />
        <child link="robot2/link3" />
        <origin rpy="0 0 0" xyz="0.0 0.069 0.033" />
        <axis xyz="0 1 0" />
        <limit effort="1000" lower="-1.57079632679" upper="1.57079632679" velocity="6.5" />
        <dynamics damping="0.7" />
    </joint>
    <!-- link 3 -->
    <link name="robot2/link3">
        <visual>
            <origin xyz="0.067 0.008 -0.019" rpy="0 0 3.14"/>
            <geometry>
                <mesh filename="package://open_manipulator_p_description/meshes/link3_papras.stl" scale="0.001 0.001 0.001"/>
            </geometry>
            <material name="grey" />
        </visual>
        <collision>
            <origin xyz="0.067 0.008 -0.019" rpy="0 0 3.14"/>
            <geometry>
                <mesh filename="package://open_manipulator_p_description/meshes/link3_papras.stl" scale="0.001 0.001 0.001"/>
            </geometry>
        </collision>
        
<inertial>
            <origin rpy="0 0 0" xyz="0.01768 -0.06881 0.20524" />
            <!--<origin xyz="-0.01232 -0.05731 -0.05876" rpy="0 0 0"/>-->
            <mass value="1.30260" />
            <inertia ixx="1.0" ixy="0.0" ixz="0.0" iyy="1.0" iyz="0.0" izz="1.0" />
            <!--<inertia ixx="0.01111021" ixy="0.00001331" ixz="-0.00134208" iyy="0.01046642" iyz="0.00016235" izz="0.00202081" />-->
        </inertial>

    </link>
    <!-- Joint 3 -->
    <joint name="robot2/joint3" type="revolute">
        <parent link="robot2/link3" />
        <child link="robot2/link4" />
        <origin rpy="0 0 0" xyz="0.03000 -0.01150 0.26400" />
        <axis xyz="0 1 0" />
        <limit effort="1000" lower="-1.57079632679" upper="1.57079632679" velocity="6.5" />
        <dynamics damping="0.7" />
    </joint>
    <!-- link 4 -->
    <link name="robot2/link4">
        <visual>
            <origin xyz="0.227 0.0085 -0.024" rpy="0 0 3.14"/>
            <geometry>
                <mesh filename="package://open_manipulator_p_description/meshes/link4_papras.stl" scale="0.001 0.001 0.001"/>
            </geometry>
            <material name="grey" />
        </visual>
        <collision>
            <origin xyz="0.227 0.0085 -0.024" rpy="0 0 3.14"/>
            <geometry>
                <mesh filename="package://open_manipulator_p_description/meshes/link4_papras.stl" scale="0.001 0.001 0.001"/>
            </geometry>
        </collision>
        
<inertial>
            <origin rpy="0 0 0" xyz="0.12475 -0.05716 0.02979" />
            <!--<origin xyz="-0.07025 0.00034 -0.00021" rpy="0 0 0"/>-->
            <mass value="1.15977" />
            <inertia ixx="1.0" ixy="0.0" ixz="0.0" iyy="1.0" iyz="0.0" izz="1.0" />
            <!--<inertia ixx="0.00096726" ixy="0.00004383" ixz="-0.00002771" iyy="0.00318801" iyz="0.00000627" izz="0.00341484" />-->
        </inertial>

    </link>
    <!-- Joint 4 -->
    <joint name="robot2/joint4" type="revolute">
        <parent link="robot2/link4" />
        <child link="robot2/link5" />
        <origin rpy="0 0 0" xyz="0.19500 -0.05750 0.03000" />
        <axis xyz="1 0 0" />
        <limit effort="1000" lower="-1.57079632679" upper="1.57079632679" velocity="6.5" />
        <dynamics damping="0.7" />
    </joint>
    <!-- link 5 -->
    <link name="robot2/link5">
        <visual>
            <origin rpy="0 0 0" xyz="0 0 0" />
            <geometry>
                <mesh filename="package://open_manipulator_p_description/meshes/link5.stl" scale="0.001 0.001 0.001" />
            </geometry>
            <material name="grey" />
        </visual>
        <collision>
            <origin rpy="0 0 0" xyz="0 0 0" />
            <geometry>
                <mesh filename="package://open_manipulator_p_description/meshes/link5.stl" scale="0.001 0.001 0.001" />
            </geometry>
        </collision>
        
<inertial>
            <origin rpy="0 0 0" xyz="0.05642 -0.00217 0.00002" />
            <!--<origin xyz="-0.00658 -0.04717 0.00002" rpy="0 0 0"/>-->
            <mass value="0.44688" />
            <inertia ixx="1.0" ixy="0.0" ixz="0.0" iyy="1.0" iyz="0.0" izz="1.0" />
            <!--<inertia ixx="0.00030285" ixy="0.00000761" ixz="0.00000031" iyy="0.00022339" iyz="-0.00000001" izz="0.00039766" />-->
        </inertial>

    </link>
    <!-- Joint 5 -->
    <joint name="robot2/joint5" type="revolute">
        <parent link="robot2/link5" />
        <child link="robot2/link6" />
        <origin rpy="0 0 0" xyz="0.06300 0.04500 0.00000" />
        <axis xyz="0 1 0" />
        <limit effort="1000" lower="-1.57079632679" upper="1.57079632679" velocity="6.5" />
        <dynamics damping="0.7" />
    </joint>
    <!-- link 6 -->
    <link name="robot2/link6">
        <visual>
            <origin xyz="-0.034 -0.098 -0.028" rpy="0 0 0"/>
            <geometry>
                <mesh filename="package://open_manipulator_p_description/meshes/link6_papras.stl" scale="0.001 0.001 0.001"/>
            </geometry>
            <material name="grey" />
        </visual>
        <collision>
            <origin xyz="-0.034 -0.098 -0.028" rpy="0 0 0"/>
            <geometry>
                <mesh filename="package://open_manipulator_p_description/meshes/link6_papras.stl" scale="0.001 0.001 0.001"/>
            </geometry>
        </collision>
        
<inertial>
            <origin rpy="0 0 0" xyz="0.06831 -0.04457 0.00000" />
            <!--<origin xyz="-0.05469 0.00043 0.00000" rpy="0 0 0"/>-->
            <mass value="0.43273" />
            <inertia ixx="1.0" ixy="0.0" ixz="0.0" iyy="1.0" iyz="0.0" izz="1.0" />
            <!--<inertia ixx="0.00021512" ixy="0.00001009" ixz="0.00000000" iyy="0.00042827" iyz="0.00000000" izz="0.00051436" />-->
        </inertial>

    </link>
    <!-- Joint 6 -->
    <joint name="robot2/joint6" type="revolute">
        <parent link="robot2/link6" />
        <child link="robot2/end_link" />
        <origin rpy="0 0 0" xyz="0.12300 -0.04500 0.00000" />
        <axis xyz="1 0 0" />
        <limit effort="1000" lower="-1.57079632679" upper="1.57079632679" velocity="6.5" />
        <dynamics damping="0.7" />
    </joint>
    <!-- end link -->
    <link name="robot2/end_link">
        <visual>
            <origin rpy="0 0 0" xyz="0.0 0.0 0.0" />
            <geometry>
                <mesh filename="package://open_manipulator_p_description/meshes/end_link.stl" scale="0.001 0.001 0.001" />
            </geometry>
            <material name="grey" />
        </visual>
        <collision>
            <origin rpy="0 0 0" xyz="0.0 0.0 0.0" />
            <geometry>
                <mesh filename="package://open_manipulator_p_description/meshes/end_link.stl" scale="0.001 0.001 0.001" />
            </geometry>
        </collision>
        
<inertial>
            <origin rpy="0 0 0" xyz="0.00337 0.00000 0.00000" />
            <mass value="0.01919" />
            <inertia ixx="1.0" ixy="0.0" ixz="0.0" iyy="1.0" iyz="0.0" izz="1.0" />
            <!--<inertia ixx="0.00000938" ixy="0.0" ixz="0.0" iyy="0.00000338" iyz="0.0" izz="0.00000635" />-->
        </inertial>

    </link>
    <joint name="robot3/world_fixed" type="fixed">
        <parent link="world" />
        <child link="robot3/link1" />
        <origin rpy="0 0 -1.57" xyz="0.3 0.0 0.853625" />
    </joint>
    <!-- link 1 -->
    <link name="robot3/link1">
        <visual>
            <origin rpy="0 0 0" xyz="0 0 0" />
            <geometry>
                <mesh filename="package://open_manipulator_p_description/meshes/link1.stl" scale="0.001 0.001 0.001" />
            </geometry>
            <material name="grey" />
        </visual>
        <collision>
            <origin rpy="0 0 0" xyz="0 0 0" />
            <geometry>
                <mesh filename="package://open_manipulator_p_description/meshes/link1.stl" scale="0.001 0.001 0.001" />
            </geometry>
        </collision>
        
<inertial>
            <origin rpy="0 0 0" xyz="0.00023 0.00000 0.06223" />
            <mass value="0.85644" />
            <inertia ixx="1.0" ixy="0.0" ixz="0.0" iyy="1.0" iyz="0.0" izz="1.0" />
            <!--<inertia ixx="0.00121064" ixy="0.0" ixz="0.00001100" iyy="0.00120886" iyz="0.0" izz="0.00038103" />-->
        </inertial>

    </link>
    <!-- Joint 1 -->
    <joint name="robot3/joint1" type="revolute">
        <parent link="robot3/link1" />
        <child link="robot3/link2" />
        <origin rpy="0 0 0" xyz="0.0 0.0 0.126" />
        <axis xyz="0 0 1" />
        <limit effort="1000" lower="-1.57079632679" upper="1.57079632679" velocity="6.5" />
        <dynamics damping="0.7" />
    </joint>
    <!-- link 2 -->
    <link name="robot3/link2">
        <visual>
            <origin rpy="0 0 0" xyz="0 0 0" />
            <geometry>
                <mesh filename="package://open_manipulator_p_description/meshes/link2.stl" scale="0.001 0.001 0.001" />
            </geometry>
            <material name="grey" />
        </visual>
        <collision>
            <origin rpy="0 0 0" xyz="0 0 0" />
            <geometry>
                <mesh filename="package://open_manipulator_p_description/meshes/link2.stl" scale="0.001 0.001 0.001" />
            </geometry>
        </collision>
        
<inertial>
            <origin rpy="0 0 0" xyz="0.00000 0.00080 0.03183" />
            <!--<origin xyz="0.00000 -0.06820 -0.00117" rpy="0 0 0"/>-->
            <mass value="0.94658" />
            <inertia ixx="1.0" ixy="0.0" ixz="0.0" iyy="1.0" iyz="0.0" izz="1.0" />
            <!--<inertia ixx="0.00152547" ixy="0.0" ixz="0.0" iyy="0.00045954" iyz="-0.00001086" izz="0.00151740" />-->
        </inertial>

    </link>
    <!-- Joint 2 -->
    <joint name="robot3/joint2" type="revolute">
        <parent link="robot3/link2" />
        <child link="robot3/link3" />
        <origin rpy="0 0 0" xyz="0.0 0.069 0.033" />
        <axis xyz="0 1 0" />
        <limit effort="1000" lower="-1.57079632679" upper="1.57079632679" velocity="6.5" />
        <dynamics damping="0.7" />
    </joint>
    <!-- link 3 -->
    <link name="robot3/link3">
        <visual>
            <origin xyz="0.067 0.008 -0.019" rpy="0 0 3.14"/>
            <geometry>
                <mesh filename="package://open_manipulator_p_description/meshes/link3_papras.stl" scale="0.001 0.001 0.001"/>
            </geometry>
            <material name="grey" />
        </visual>
        <collision>
            <origin xyz="0.067 0.008 -0.019" rpy="0 0 3.14"/>
            <geometry>
                <mesh filename="package://open_manipulator_p_description/meshes/link3_papras.stl" scale="0.001 0.001 0.001"/>
            </geometry>
        </collision>
        
<inertial>
            <origin rpy="0 0 0" xyz="0.01768 -0.06881 0.20524" />
            <!--<origin xyz="-0.01232 -0.05731 -0.05876" rpy="0 0 0"/>-->
            <mass value="1.30260" />
            <inertia ixx="1.0" ixy="0.0" ixz="0.0" iyy="1.0" iyz="0.0" izz="1.0" />
            <!--<inertia ixx="0.01111021" ixy="0.00001331" ixz="-0.00134208" iyy="0.01046642" iyz="0.00016235" izz="0.00202081" />-->
        </inertial>

    </link>
    <!-- Joint 3 -->
    <joint name="robot3/joint3" type="revolute">
        <parent link="robot3/link3" />
        <child link="robot3/link4" />
        <origin rpy="0 0 0" xyz="0.03000 -0.01150 0.26400" />
        <axis xyz="0 1 0" />
        <limit effort="1000" lower="-1.57079632679" upper="1.57079632679" velocity="6.5" />
        <dynamics damping="0.7" />
    </joint>
    <!-- link 4 -->
    <link name="robot3/link4">
        <visual>
            <origin xyz="0.227 0.0085 -0.024" rpy="0 0 3.14"/>
            <geometry>
                <mesh filename="package://open_manipulator_p_description/meshes/link4_papras.stl" scale="0.001 0.001 0.001"/>
            </geometry>
            <material name="grey" />
        </visual>
        <collision>
            <origin xyz="0.227 0.0085 -0.024" rpy="0 0 3.14"/>
            <geometry>
                <mesh filename="package://open_manipulator_p_description/meshes/link4_papras.stl" scale="0.001 0.001 0.001"/>
            </geometry>
        </collision>
        
<inertial>
            <origin rpy="0 0 0" xyz="0.12475 -0.05716 0.02979" />
            <!--<origin xyz="-0.07025 0.00034 -0.00021" rpy="0 0 0"/>-->
            <mass value="1.15977" />
            <inertia ixx="1.0" ixy="0.0" ixz="0.0" iyy="1.0" iyz="0.0" izz="1.0" />
            <!--<inertia ixx="0.00096726" ixy="0.00004383" ixz="-0.00002771" iyy="0.00318801" iyz="0.00000627" izz="0.00341484" />-->
        </inertial>

    </link>
    <!-- Joint 4 -->
    <joint name="robot3/joint4" type="revolute">
        <parent link="robot3/link4" />
        <child link="robot3/link5" />
        <origin rpy="0 0 0" xyz="0.19500 -0.05750 0.03000" />
        <axis xyz="1 0 0" />
        <limit effort="1000" lower="-1.57079632679" upper="1.57079632679" velocity="6.5" />
        <dynamics damping="0.7" />
    </joint>
    <!-- link 5 -->
    <link name="robot3/link5">
        <visual>
            <origin rpy="0 0 0" xyz="0 0 0" />
            <geometry>
                <mesh filename="package://open_manipulator_p_description/meshes/link5.stl" scale="0.001 0.001 0.001" />
            </geometry>
            <material name="grey" />
        </visual>
        <collision>
            <origin rpy="0 0 0" xyz="0 0 0" />
            <geometry>
                <mesh filename="package://open_manipulator_p_description/meshes/link5.stl" scale="0.001 0.001 0.001" />
            </geometry>
        </collision>
        
<inertial>
            <origin rpy="0 0 0" xyz="0.05642 -0.00217 0.00002" />
            <!--<origin xyz="-0.00658 -0.04717 0.00002" rpy="0 0 0"/>-->
            <mass value="0.44688" />
            <inertia ixx="1.0" ixy="0.0" ixz="0.0" iyy="1.0" iyz="0.0" izz="1.0" />
            <!--<inertia ixx="0.00030285" ixy="0.00000761" ixz="0.00000031" iyy="0.00022339" iyz="-0.00000001" izz="0.00039766" />-->
        </inertial>

    </link>
    <!-- Joint 5 -->
    <joint name="robot3/joint5" type="revolute">
        <parent link="robot3/link5" />
        <child link="robot3/link6" />
        <origin rpy="0 0 0" xyz="0.06300 0.04500 0.00000" />
        <axis xyz="0 1 0" />
        <limit effort="1000" lower="-1.57079632679" upper="1.57079632679" velocity="6.5" />
        <dynamics damping="0.7" />
    </joint>
    <!-- link 6 -->
    <link name="robot3/link6">
        <visual>
            <origin xyz="-0.034 -0.098 -0.028" rpy="0 0 0"/>
            <geometry>
                <mesh filename="package://open_manipulator_p_description/meshes/link6_papras.stl" scale="0.001 0.001 0.001"/>
            </geometry>
            <material name="grey" />
        </visual>
        <collision>
            <origin xyz="-0.034 -0.098 -0.028" rpy="0 0 0"/>
            <geometry>
                <mesh filename="package://open_manipulator_p_description/meshes/link6_papras.stl" scale="0.001 0.001 0.001"/>
            </geometry>
        </collision>
        
<inertial>
            <origin rpy="0 0 0" xyz="0.06831 -0.04457 0.00000" />
            <!--<origin xyz="-0.05469 0.00043 0.00000" rpy="0 0 0"/>-->
            <mass value="0.43273" />
            <inertia ixx="1.0" ixy="0.0" ixz="0.0" iyy="1.0" iyz="0.0" izz="1.0" />
            <!--<inertia ixx="0.00021512" ixy="0.00001009" ixz="0.00000000" iyy="0.00042827" iyz="0.00000000" izz="0.00051436" />-->
        </inertial>

    </link>
    <!-- Joint 6 -->
    <joint name="robot3/joint6" type="revolute">
        <parent link="robot3/link6" />
        <child link="robot3/end_link" />
        <origin rpy="0 0 0" xyz="0.12300 -0.04500 0.00000" />
        <axis xyz="1 0 0" />
        <limit effort="1000" lower="-1.57079632679" upper="1.57079632679" velocity="6.5" />
        <dynamics damping="0.7" />
    </joint>
    <!-- end link -->
    <link name="robot3/end_link">
        <visual>
            <origin rpy="0 0 0" xyz="0.0 0.0 0.0" />
            <geometry>
                <mesh filename="package://open_manipulator_p_description/meshes/end_link.stl" scale="0.001 0.001 0.001" />
            </geometry>
            <material name="grey" />
        </visual>
        <collision>
            <origin rpy="0 0 0" xyz="0.0 0.0 0.0" />
            <geometry>
                <mesh filename="package://open_manipulator_p_description/meshes/end_link.stl" scale="0.001 0.001 0.001" />
            </geometry>
        </collision>
        
<inertial>
            <origin rpy="0 0 0" xyz="0.00337 0.00000 0.00000" />
            <mass value="0.01919" />
            <inertia ixx="1.0" ixy="0.0" ixz="0.0" iyy="1.0" iyz="0.0" izz="1.0" />
            <!--<inertia ixx="0.00000938" ixy="0.0" ixz="0.0" iyy="0.00000338" iyz="0.0" izz="0.00000635" />-->
        </inertial>

    </link>
    <transmission name="trans_robot1/joint1">
        <type>transmission_interface/SimpleTransmission</type>
        <joint name="robot1/joint1">
            <hardwareInterface>hardware_interface/PositionJointInterface</hardwareInterface>
        </joint>
        <actuator name="robot1/joint1_motor">
            <hardwareInterface>hardware_interface/PositionJointInterface</hardwareInterface>
            <mechanicalReduction>1</mechanicalReduction>
        </actuator>
    </transmission>
    <transmission name="trans_robot1/joint2">
        <type>transmission_interface/SimpleTransmission</type>
        <joint name="robot1/joint2">
            <hardwareInterface>hardware_interface/PositionJointInterface</hardwareInterface>
        </joint>
        <actuator name="robot1/joint2_motor">
            <hardwareInterface>hardware_interface/PositionJointInterface</hardwareInterface>
            <mechanicalReduction>1</mechanicalReduction>
        </actuator>
    </transmission>
    <transmission name="trans_robot1/joint3">
        <type>transmission_interface/SimpleTransmission</type>
        <joint name="robot1/joint3">
            <hardwareInterface>hardware_interface/PositionJointInterface</hardwareInterface>
        </joint>
        <actuator name="robot1/joint3_motor">
            <hardwareInterface>hardware_interface/PositionJointInterface</hardwareInterface>
            <mechanicalReduction>1</mechanicalReduction>
        </actuator>
    </transmission>
    <transmission name="trans_robot1/joint4">
        <type>transmission_interface/SimpleTransmission</type>
        <joint name="robot1/joint4">
            <hardwareInterface>hardware_interface/PositionJointInterface</hardwareInterface>
        </joint>
        <actuator name="robot1/joint4_motor">
            <hardwareInterface>hardware_interface/PositionJointInterface</hardwareInterface>
            <mechanicalReduction>1</mechanicalReduction>
        </actuator>
    </transmission>
    <transmission name="trans_robot1/joint5">
        <type>transmission_interface/SimpleTransmission</type>
        <joint name="robot1/joint5">
            <hardwareInterface>hardware_interface/PositionJointInterface</hardwareInterface>
        </joint>
        <actuator name="robot1/joint5_motor">
            <hardwareInterface>hardware_interface/PositionJointInterface</hardwareInterface>
            <mechanicalReduction>1</mechanicalReduction>
        </actuator>
    </transmission>
    <transmission name="trans_robot1/joint6">
        <type>transmission_interface/SimpleTransmission</type>
        <joint name="robot1/joint6">
            <hardwareInterface>hardware_interface/PositionJointInterface</hardwareInterface>
        </joint>
        <actuator name="robot1/joint6_motor">
            <hardwareInterface>hardware_interface/PositionJointInterface</hardwareInterface>
            <mechanicalReduction>1</mechanicalReduction>
        </actuator>
    </transmission>
    <transmission name="trans_robot2/joint1">
        <type>transmission_interface/SimpleTransmission</type>
        <joint name="robot2/joint1">
            <hardwareInterface>hardware_interface/PositionJointInterface</hardwareInterface>
        </joint>
        <actuator name="robot2/joint1_motor">
            <hardwareInterface>hardware_interface/PositionJointInterface</hardwareInterface>
            <mechanicalReduction>1</mechanicalReduction>
        </actuator>
    </transmission>
    <transmission name="trans_robot2/joint2">
        <type>transmission_interface/SimpleTransmission</type>
        <joint name="robot2/joint2">
            <hardwareInterface>hardware_interface/PositionJointInterface</hardwareInterface>
        </joint>
        <actuator name="robot2/joint2_motor">
            <hardwareInterface>hardware_interface/PositionJointInterface</hardwareInterface>
            <mechanicalReduction>1</mechanicalReduction>
        </actuator>
    </transmission>
    <transmission name="trans_robot2/joint3">
        <type>transmission_interface/SimpleTransmission</type>
        <joint name="robot2/joint3">
            <hardwareInterface>hardware_interface/PositionJointInterface</hardwareInterface>
        </joint>
        <actuator name="robot2/joint3_motor">
            <hardwareInterface>hardware_interface/PositionJointInterface</hardwareInterface>
            <mechanicalReduction>1</mechanicalReduction>
        </actuator>
    </transmission>
    <transmission name="trans_robot2/joint4">
        <type>transmission_interface/SimpleTransmission</type>
        <joint name="robot2/joint4">
            <hardwareInterface>hardware_interface/PositionJointInterface</hardwareInterface>
        </joint>
        <actuator name="robot2/joint4_motor">
            <hardwareInterface>hardware_interface/PositionJointInterface</hardwareInterface>
            <mechanicalReduction>1</mechanicalReduction>
        </actuator>
    </transmission>
    <transmission name="trans_robot2/joint5">
        <type>transmission_interface/SimpleTransmission</type>
        <joint name="robot2/joint5">
            <hardwareInterface>hardware_interface/PositionJointInterface</hardwareInterface>
        </joint>
        <actuator name="robot2/joint5_motor">
            <hardwareInterface>hardware_interface/PositionJointInterface</hardwareInterface>
            <mechanicalReduction>1</mechanicalReduction>
        </actuator>
    </transmission>
    <transmission name="trans_robot2/joint6">
        <type>transmission_interface/SimpleTransmission</type>
        <joint name="robot2/joint6">
            <hardwareInterface>hardware_interface/PositionJointInterface</hardwareInterface>
        </joint>
        <actuator name="robot2/joint6_motor">
            <hardwareInterface>hardware_interface/PositionJointInterface</hardwareInterface>
            <mechanicalReduction>1</mechanicalReduction>
        </actuator>
    </transmission>
    <transmission name="trans_robot3/joint1">
        <type>transmission_interface/SimpleTransmission</type>
        <joint name="robot3/joint1">
            <hardwareInterface>hardware_interface/PositionJointInterface</hardwareInterface>
        </joint>
        <actuator name="robot3/joint1_motor">
            <hardwareInterface>hardware_interface/PositionJointInterface</hardwareInterface>
            <mechanicalReduction>1</mechanicalReduction>
        </actuator>
    </transmission>
    <transmission name="trans_robot3/joint2">
        <type>transmission_interface/SimpleTransmission</type>
        <joint name="robot3/joint2">
            <hardwareInterface>hardware_interface/PositionJointInterface</hardwareInterface>
        </joint>
        <actuator name="robot3/joint2_motor">
            <hardwareInterface>hardware_interface/PositionJointInterface</hardwareInterface>
            <mechanicalReduction>1</mechanicalReduction>
        </actuator>
    </transmission>
    <transmission name="trans_robot3/joint3">
        <type>transmission_interface/SimpleTransmission</type>
        <joint name="robot3/joint3">
            <hardwareInterface>hardware_interface/PositionJointInterface</hardwareInterface>
        </joint>
        <actuator name="robot3/joint3_motor">
            <hardwareInterface>hardware_interface/PositionJointInterface</hardwareInterface>
            <mechanicalReduction>1</mechanicalReduction>
        </actuator>
    </transmission>
    <transmission name="trans_robot3/joint4">
        <type>transmission_interface/SimpleTransmission</type>
        <joint name="robot3/joint4">
            <hardwareInterface>hardware_interface/PositionJointInterface</hardwareInterface>
        </joint>
        <actuator name="robot3/joint4_motor">
            <hardwareInterface>hardware_interface/PositionJointInterface</hardwareInterface>
            <mechanicalReduction>1</mechanicalReduction>
        </actuator>
    </transmission>
    <transmission name="trans_robot3/joint5">
        <type>transmission_interface/SimpleTransmission</type>
        <joint name="robot3/joint5">
            <hardwareInterface>hardware_interface/PositionJointInterface</hardwareInterface>
        </joint>
        <actuator name="robot3/joint5_motor">
            <hardwareInterface>hardware_interface/PositionJointInterface</hardwareInterface>
            <mechanicalReduction>1</mechanicalReduction>
        </actuator>
    </transmission>
    <transmission name="trans_robot3/joint6">
        <type>transmission_interface/SimpleTransmission</type>
        <joint name="robot3/joint6">
            <hardwareInterface>hardware_interface/PositionJointInterface</hardwareInterface>
        </joint>
        <actuator name="robot3/joint6_motor">
            <hardwareInterface>hardware_interface/PositionJointInterface</hardwareInterface>
            <mechanicalReduction>1</mechanicalReduction>
        </actuator>
    </transmission>
    <gazebo>
        <plugin name="gazebo_ros_control" filename="libgazebo_ros_control.so">
            <robotNamespace>/</robotNamespace>
        </plugin>
    </gazebo>
</robot>

<transmission name="robot1/tran1">
        <type>transmission_interface/SimpleTransmission</type>
        <joint name="robot1/joint1">
            <hardwareInterface>hardware_interface/PositionJointInterface</hardwareInterface>
        </joint>
        <actuator name="robot1/motor1">
            <mechanicalReduction>1</mechanicalReduction>
        </actuator>
    </transmission>
    <transmission name="robot2/tran1">
        <type>transmission_interface/SimpleTransmission</type>
        <joint name="robot2/joint1">
            <hardwareInterface>hardware_interface/PositionJointInterface</hardwareInterface>
        </joint>
        <actuator name="robot2/motor1">
            <mechanicalReduction>1</mechanicalReduction>
        </actuator>
    </transmission>
    <transmission name="robot3/tran1">
        <type>transmission_interface/SimpleTransmission</type>
        <joint name="robot3/joint1">
            <hardwareInterface>hardware_interface/PositionJointInterface</hardwareInterface>
        </joint>
        <actuator name="robot3/motor1">
            <mechanicalReduction>1</mechanicalReduction>
        </actuator>
    </transmission>
    <transmission name="robot1/tran2">
        <type>transmission_interface/SimpleTransmission</type>
        <joint name="robot1/joint2">
            <hardwareInterface>hardware_interface/PositionJointInterface</hardwareInterface>
        </joint>
        <actuator name="robot1/motor2">
            <mechanicalReduction>1</mechanicalReduction>
        </actuator>
    </transmission>
    <transmission name="robot2/tran2">
        <type>transmission_interface/SimpleTransmission</type>
        <joint name="robot2/joint2">
            <hardwareInterface>hardware_interface/PositionJointInterface</hardwareInterface>
        </joint>
        <actuator name="robot2/motor2">
            <mechanicalReduction>1</mechanicalReduction>
        </actuator>
    </transmission>
    <transmission name="robot3/tran2">
        <type>transmission_interface/SimpleTransmission</type>
        <joint name="robot3/joint2">
            <hardwareInterface>hardware_interface/PositionJointInterface</hardwareInterface>
        </joint>
        <actuator name="robot3/motor2">
            <mechanicalReduction>1</mechanicalReduction>
        </actuator>
    </transmission>
    <transmission name="robot1/tran3">
        <type>transmission_interface/SimpleTransmission</type>
        <joint name="robot1/joint3">
            <hardwareInterface>hardware_interface/PositionJointInterface</hardwareInterface>
        </joint>
        <actuator name="robot1/motor3">
            <mechanicalReduction>1</mechanicalReduction>
        </actuator>
    </transmission>
    <transmission name="robot2/tran3">
        <type>transmission_interface/SimpleTransmission</type>
        <joint name="robot2/joint3">
            <hardwareInterface>hardware_interface/PositionJointInterface</hardwareInterface>
        </joint>
        <actuator name="robot2/motor3">
            <mechanicalReduction>1</mechanicalReduction>
        </actuator>
    </transmission>
    <transmission name="robot3/tran3">
        <type>transmission_interface/SimpleTransmission</type>
        <joint name="robot3/joint3">
            <hardwareInterface>hardware_interface/PositionJointInterface</hardwareInterface>
        </joint>
        <actuator name="robot3/motor3">
            <mechanicalReduction>1</mechanicalReduction>
        </actuator>
    </transmission>
    <transmission name="robot1/tran4">
        <type>transmission_interface/SimpleTransmission</type>
        <joint name="robot1/joint4">
            <hardwareInterface>hardware_interface/PositionJointInterface</hardwareInterface>
        </joint>
        <actuator name="robot1/motor4">
            <mechanicalReduction>1</mechanicalReduction>
        </actuator>
    </transmission>
    <transmission name="robot2/tran4">
        <type>transmission_interface/SimpleTransmission</type>
        <joint name="robot2/joint4">
            <hardwareInterface>hardware_interface/PositionJointInterface</hardwareInterface>
        </joint>
        <actuator name="robot2/motor4">
            <mechanicalReduction>1</mechanicalReduction>
        </actuator>
    </transmission>
    <transmission name="robot3/tran4">
        <type>transmission_interface/SimpleTransmission</type>
        <joint name="robot3/joint4">
            <hardwareInterface>hardware_interface/PositionJointInterface</hardwareInterface>
        </joint>
        <actuator name="robot3/motor4">
            <mechanicalReduction>1</mechanicalReduction>
        </actuator>
    </transmission>
    <transmission name="robot1/tran5">
        <type>transmission_interface/SimpleTransmission</type>
        <joint name="robot1/joint5">
            <hardwareInterface>hardware_interface/PositionJointInterface</hardwareInterface>
        </joint>
        <actuator name="robot1/motor5">
            <mechanicalReduction>1</mechanicalReduction>
        </actuator>
    </transmission>
    <transmission name="robot2/tran5">
        <type>transmission_interface/SimpleTransmission</type>
        <joint name="robot2/joint5">
            <hardwareInterface>hardware_interface/PositionJointInterface</hardwareInterface>
        </joint>
        <actuator name="robot2/motor5">
            <mechanicalReduction>1</mechanicalReduction>
        </actuator>
    </transmission>
    <transmission name="robot3/tran5">
        <type>transmission_interface/SimpleTransmission</type>
        <joint name="robot3/joint5">
            <hardwareInterface>hardware_interface/PositionJointInterface</hardwareInterface>
        </joint>
        <actuator name="robot3/motor5">
            <mechanicalReduction>1</mechanicalReduction>
        </actuator>
    </transmission>
    <transmission name="robot1/tran6">
        <type>transmission_interface/SimpleTransmission</type>
        <joint name="robot1/joint6">
            <hardwareInterface>hardware_interface/PositionJointInterface</hardwareInterface>
        </joint>
        <actuator name="robot1/motor6">
            <mechanicalReduction>1</mechanicalReduction>
        </actuator>
    </transmission>
    <transmission name="robot2/tran6">
        <type>transmission_interface/SimpleTransmission</type>
        <joint name="robot2/joint6">
            <hardwareInterface>hardware_interface/PositionJointInterface</hardwareInterface>
        </joint>
        <actuator name="robot2/motor6">
            <mechanicalReduction>1</mechanicalReduction>
        </actuator>
    </transmission>
    <transmission name="robot3/tran6">
        <type>transmission_interface/SimpleTransmission</type>
        <joint name="robot3/joint6">
            <hardwareInterface>hardware_interface/PositionJointInterface</hardwareInterface>
        </joint>
        <actuator name="robot3/motor6">
            <mechanicalReduction>1</mechanicalReduction>
        </actuator>
    </transmission>
    <!-- World -->
    <link name="world" />
    <joint name="robot1/world_fixed" type="fixed">
        <parent link="world" />
        <child link="robot1/link1" />
        <origin rpy="0 0 1.57" xyz="-0.3 0.1 0.853625" />
    </joint>
    <!-- link 1 -->
    <link name="robot1/link1">
        <visual>
            <origin rpy="0 0 0" xyz="0 0 0" />
            <geometry>
                <mesh filename="package://open_manipulator_p_description/meshes/link1.stl" scale="0.001 0.001 0.001" />
            </geometry>
            <material name="grey" />
        </visual>
        <collision>
            <origin rpy="0 0 0" xyz="0 0 0" />
            <geometry>
                <mesh filename="package://open_manipulator_p_description/meshes/link1.stl" scale="0.001 0.001 0.001" />
            </geometry>
        </collision>
        <inertial>
            <origin rpy="0 0 0" xyz="0.00023 0.00000 0.06223" />
            <mass value="0.85644" />
            <inertia ixx="1.0" ixy="0.0" ixz="0.0" iyy="1.0" iyz="0.0" izz="1.0" />
            <!--<inertia ixx="0.00121064" ixy="0.0" ixz="0.00001100" iyy="0.00120886" iyz="0.0" izz="0.00038103" />-->
        </inertial>
    </link>
    <!-- Joint 1 -->
    <joint name="robot1/joint1" type="revolute">
        <parent link="robot1/link1" />
        <child link="robot1/link2" />
        <origin rpy="0 0 0" xyz="0.0 0.0 0.126" />
        <axis xyz="0 0 1" />
        <limit effort="1000" lower="-1.57079632679" upper="1.57079632679" velocity="6.5" />
        <dynamics damping="0.7" />
    </joint>
    <!-- link 2 -->
    <link name="robot1/link2">
        <visual>
            <origin rpy="0 0 0" xyz="0 0 0" />
            <geometry>
                <mesh filename="package://open_manipulator_p_description/meshes/link2.stl" scale="0.001 0.001 0.001" />
            </geometry>
            <material name="grey" />
        </visual>
        <collision>
            <origin rpy="0 0 0" xyz="0 0 0" />
            <geometry>
                <mesh filename="package://open_manipulator_p_description/meshes/link2.stl" scale="0.001 0.001 0.001" />
            </geometry>
        </collision>
        <inertial>
            <origin rpy="0 0 0" xyz="0.00000 0.00080 0.03183" />
            <!--<origin xyz="0.00000 -0.06820 -0.00117" rpy="0 0 0"/>-->
            <mass value="0.94658" />
            <inertia ixx="1.0" ixy="0.0" ixz="0.0" iyy="1.0" iyz="0.0" izz="1.0" />
            <!--<inertia ixx="0.00152547" ixy="0.0" ixz="0.0" iyy="0.00045954" iyz="-0.00001086" izz="0.00151740" />-->
        </inertial>
    </link>
    <!-- Joint 2 -->
    <joint name="robot1/joint2" type="revolute">
        <parent link="robot1/link2" />
        <child link="robot1/link3" />
        <origin rpy="0 0 0" xyz="0.0 0.069 0.033" />
        <axis xyz="0 1 0" />
        <limit effort="1000" lower="-1.57079632679" upper="1.57079632679" velocity="6.5" />
        <dynamics damping="0.7" />
    </joint>
    <!-- link 3 -->
    <link name="robot1/link3">
        <visual>
            <origin xyz="0.067 0.008 -0.019" rpy="0 0 3.14"/>
            <geometry>
                <mesh filename="package://open_manipulator_p_description/meshes/link3_papras.stl" scale="0.001 0.001 0.001"/>
            </geometry>
            <material name="grey" />
        </visual>
        <collision>
            <origin xyz="0.067 0.008 -0.019" rpy="0 0 3.14"/>
            <geometry>
                <mesh filename="package://open_manipulator_p_description/meshes/link3_papras.stl" scale="0.001 0.001 0.001"/>
            </geometry>
        </collision>
        <inertial>
            <origin rpy="0 0 0" xyz="0.01768 -0.06881 0.20524" />
            <!--<origin xyz="-0.01232 -0.05731 -0.05876" rpy="0 0 0"/>-->
            <mass value="1.30260" />
            <inertia ixx="1.0" ixy="0.0" ixz="0.0" iyy="1.0" iyz="0.0" izz="1.0" />
            <!--<inertia ixx="0.01111021" ixy="0.00001331" ixz="-0.00134208" iyy="0.01046642" iyz="0.00016235" izz="0.00202081" />-->
        </inertial>
    </link>
    <!-- Joint 3 -->
    <joint name="robot1/joint3" type="revolute">
        <parent link="robot1/link3" />
        <child link="robot1/link4" />
        <origin rpy="0 0 0" xyz="0.03000 -0.01150 0.26400" />
        <axis xyz="0 1 0" />
        <limit effort="1000" lower="-1.57079632679" upper="1.57079632679" velocity="6.5" />
        <dynamics damping="0.7" />
    </joint>
    <!-- link 4 -->
    <link name="robot1/link4">
        <visual>
            <origin xyz="0.227 0.0085 -0.024" rpy="0 0 3.14"/>
            <geometry>
                <mesh filename="package://open_manipulator_p_description/meshes/link4_papras.stl" scale="0.001 0.001 0.001"/>
            </geometry>
            <material name="grey" />
        </visual>
        <collision>
            <origin xyz="0.227 0.0085 -0.024" rpy="0 0 3.14"/>
            <geometry>
                <mesh filename="package://open_manipulator_p_description/meshes/link4_papras.stl" scale="0.001 0.001 0.001"/>
            </geometry>
        </collision>
        <inertial>
            <origin rpy="0 0 0" xyz="0.12475 -0.05716 0.02979" />
            <!--<origin xyz="-0.07025 0.00034 -0.00021" rpy="0 0 0"/>-->
            <mass value="1.15977" />
            <inertia ixx="1.0" ixy="0.0" ixz="0.0" iyy="1.0" iyz="0.0" izz="1.0" />
            <!--<inertia ixx="0.00096726" ixy="0.00004383" ixz="-0.00002771" iyy="0.00318801" iyz="0.00000627" izz="0.00341484" />-->
        </inertial>
    </link>
    <!-- Joint 4 -->
    <joint name="robot1/joint4" type="revolute">
        <parent link="robot1/link4" />
        <child link="robot1/link5" />
        <origin rpy="0 0 0" xyz="0.19500 -0.05750 0.03000" />
        <axis xyz="1 0 0" />
        <limit effort="1000" lower="-1.57079632679" upper="1.57079632679" velocity="6.5" />
        <dynamics damping="0.7" />
    </joint>
    <!-- link 5 -->
    <link name="robot1/link5">
        <visual>
            <origin rpy="0 0 0" xyz="0 0 0" />
            <geometry>
                <mesh filename="package://open_manipulator_p_description/meshes/link5.stl" scale="0.001 0.001 0.001" />
            </geometry>
            <material name="grey" />
        </visual>
        <collision>
            <origin rpy="0 0 0" xyz="0 0 0" />
            <geometry>
                <mesh filename="package://open_manipulator_p_description/meshes/link5.stl" scale="0.001 0.001 0.001" />
            </geometry>
        </collision>
        <inertial>
            <origin rpy="0 0 0" xyz="0.05642 -0.00217 0.00002" />
            <!--<origin xyz="-0.00658 -0.04717 0.00002" rpy="0 0 0"/>-->
            <mass value="0.44688" />
            <inertia ixx="1.0" ixy="0.0" ixz="0.0" iyy="1.0" iyz="0.0" izz="1.0" />
            <!--<inertia ixx="0.00030285" ixy="0.00000761" ixz="0.00000031" iyy="0.00022339" iyz="-0.00000001" izz="0.00039766" />-->
        </inertial>
    </link>
    <!-- Joint 5 -->
    <joint name="robot1/joint5" type="revolute">
        <parent link="robot1/link5" />
        <child link="robot1/link6" />
        <origin rpy="0 0 0" xyz="0.06300 0.04500 0.00000" />
        <axis xyz="0 1 0" />
        <limit effort="1000" lower="-1.57079632679" upper="1.57079632679" velocity="6.5" />
        <dynamics damping="0.7" />
    </joint>
    <!-- link 6 -->
    <link name="robot1/link6">
        <visual>
            <origin xyz="-0.034 -0.098 -0.028" rpy="0 0 0"/>
            <geometry>
                <mesh filename="package://open_manipulator_p_description/meshes/link6_papras.stl" scale="0.001 0.001 0.001"/>
            </geometry>
            <material name="grey" />
        </visual>
        <collision>
            <origin xyz="-0.034 -0.098 -0.028" rpy="0 0 0"/>
            <geometry>
                <mesh filename="package://open_manipulator_p_description/meshes/link6_papras.stl" scale="0.001 0.001 0.001"/>
            </geometry>
        </collision>
        <inertial>
            <origin rpy="0 0 0" xyz="0.06831 -0.04457 0.00000" />
            <!--<origin xyz="-0.05469 0.00043 0.00000" rpy="0 0 0"/>-->
            <mass value="0.43273" />
            <inertia ixx="1.0" ixy="0.0" ixz="0.0" iyy="1.0" iyz="0.0" izz="1.0" />
            <!--<inertia ixx="0.00021512" ixy="0.00001009" ixz="0.00000000" iyy="0.00042827" iyz="0.00000000" izz="0.00051436" />-->
        </inertial>
    </link>
    <!-- Joint 6 -->
    <joint name="robot1/joint6" type="revolute">
        <parent link="robot1/link6" />
        <child link="robot1/end_link" />
        <origin rpy="0 0 0" xyz="0.12300 -0.04500 0.00000" />
        <axis xyz="1 0 0" />
        <limit effort="1000" lower="-1.57079632679" upper="1.57079632679" velocity="6.5" />
        <dynamics damping="0.7" />
    </joint>
    <!-- end link -->
    <link name="robot1/end_link">
        <visual>
            <origin rpy="0 0 0" xyz="0.0 0.0 0.0" />
            <geometry>
                <mesh filename="package://open_manipulator_p_description/meshes/end_link.stl" scale="0.001 0.001 0.001" />
            </geometry>
            <material name="grey" />
        </visual>
        <collision>
            <origin rpy="0 0 0" xyz="0.0 0.0 0.0" />
            <geometry>
                <mesh filename="package://open_manipulator_p_description/meshes/end_link.stl" scale="0.001 0.001 0.001" />
            </geometry>
        </collision>
        <inertial>
            <origin rpy="0 0 0" xyz="0.00337 0.00000 0.00000" />
            <mass value="0.01919" />
            <inertia ixx="1.0" ixy="0.0" ixz="0.0" iyy="1.0" iyz="0.0" izz="1.0" />
            <!--<inertia ixx="0.00000938" ixy="0.0" ixz="0.0" iyy="0.00000338" iyz="0.0" izz="0.00000635" />-->
        </inertial>
    </link>
    <joint name="robot2/world_fixed" type="fixed">
        <parent link="world" />
        <child link="robot2/link1" />
        <origin rpy="0 0 1.57" xyz="-0.3 -0.5 0.853625" />
    </joint>
    <!-- link 1 -->
    <link name="robot2/link1">
        <visual>
            <origin rpy="0 0 0" xyz="0 0 0" />
            <geometry>
                <mesh filename="package://open_manipulator_p_description/meshes/link1.stl" scale="0.001 0.001 0.001" />
            </geometry>
            <material name="grey" />
        </visual>
        <collision>
            <origin rpy="0 0 0" xyz="0 0 0" />
            <geometry>
                <mesh filename="package://open_manipulator_p_description/meshes/link1.stl" scale="0.001 0.001 0.001" />
            </geometry>
        </collision>
        <inertial>
            <origin rpy="0 0 0" xyz="0.00023 0.00000 0.06223" />
            <mass value="0.85644" />
            <inertia ixx="1.0" ixy="0.0" ixz="0.0" iyy="1.0" iyz="0.0" izz="1.0" />
            <!--<inertia ixx="0.00121064" ixy="0.0" ixz="0.00001100" iyy="0.00120886" iyz="0.0" izz="0.00038103" />-->
        </inertial>
    </link>
    <!-- Joint 1 -->
    <joint name="robot2/joint1" type="revolute">
        <parent link="robot2/link1" />
        <child link="robot2/link2" />
        <origin rpy="0 0 0" xyz="0.0 0.0 0.126" />
        <axis xyz="0 0 1" />
        <limit effort="1000" lower="-1.57079632679" upper="1.57079632679" velocity="6.5" />
        <dynamics damping="0.7" />
    </joint>
    <!-- link 2 -->
    <link name="robot2/link2">
        <visual>
            <origin rpy="0 0 0" xyz="0 0 0" />
            <geometry>
                <mesh filename="package://open_manipulator_p_description/meshes/link2.stl" scale="0.001 0.001 0.001" />
            </geometry>
            <material name="grey" />
        </visual>
        <collision>
            <origin rpy="0 0 0" xyz="0 0 0" />
            <geometry>
                <mesh filename="package://open_manipulator_p_description/meshes/link2.stl" scale="0.001 0.001 0.001" />
            </geometry>
        </collision>
        <inertial>
            <origin rpy="0 0 0" xyz="0.00000 0.00080 0.03183" />
            <!--<origin xyz="0.00000 -0.06820 -0.00117" rpy="0 0 0"/>-->
            <mass value="0.94658" />
            <inertia ixx="1.0" ixy="0.0" ixz="0.0" iyy="1.0" iyz="0.0" izz="1.0" />
            <!--<inertia ixx="0.00152547" ixy="0.0" ixz="0.0" iyy="0.00045954" iyz="-0.00001086" izz="0.00151740" />-->
        </inertial>
    </link>
    <!-- Joint 2 -->
    <joint name="robot2/joint2" type="revolute">
        <parent link="robot2/link2" />
        <child link="robot2/link3" />
        <origin rpy="0 0 0" xyz="0.0 0.069 0.033" />
        <axis xyz="0 1 0" />
        <limit effort="1000" lower="-1.57079632679" upper="1.57079632679" velocity="6.5" />
        <dynamics damping="0.7" />
    </joint>
    <!-- link 3 -->
    <link name="robot2/link3">
        <visual>
            <origin xyz="0.067 0.008 -0.019" rpy="0 0 3.14"/>
            <geometry>
                <mesh filename="package://open_manipulator_p_description/meshes/link3_papras.stl" scale="0.001 0.001 0.001"/>
            </geometry>
            <material name="grey" />
        </visual>
        <collision>
            <origin xyz="0.067 0.008 -0.019" rpy="0 0 3.14"/>
            <geometry>
                <mesh filename="package://open_manipulator_p_description/meshes/link3_papras.stl" scale="0.001 0.001 0.001"/>
            </geometry>
        </collision>
        <inertial>
            <origin rpy="0 0 0" xyz="0.01768 -0.06881 0.20524" />
            <!--<origin xyz="-0.01232 -0.05731 -0.05876" rpy="0 0 0"/>-->
            <mass value="1.30260" />
            <inertia ixx="1.0" ixy="0.0" ixz="0.0" iyy="1.0" iyz="0.0" izz="1.0" />
            <!--<inertia ixx="0.01111021" ixy="0.00001331" ixz="-0.00134208" iyy="0.01046642" iyz="0.00016235" izz="0.00202081" />-->
        </inertial>
    </link>
    <!-- Joint 3 -->
    <joint name="robot2/joint3" type="revolute">
        <parent link="robot2/link3" />
        <child link="robot2/link4" />
        <origin rpy="0 0 0" xyz="0.03000 -0.01150 0.26400" />
        <axis xyz="0 1 0" />
        <limit effort="1000" lower="-1.57079632679" upper="1.57079632679" velocity="6.5" />
        <dynamics damping="0.7" />
    </joint>
    <!-- link 4 -->
    <link name="robot2/link4">
        <visual>
            <origin xyz="0.227 0.0085 -0.024" rpy="0 0 3.14"/>
            <geometry>
                <mesh filename="package://open_manipulator_p_description/meshes/link4_papras.stl" scale="0.001 0.001 0.001"/>
            </geometry>
            <material name="grey" />
        </visual>
        <collision>
            <origin xyz="0.227 0.0085 -0.024" rpy="0 0 3.14"/>
            <geometry>
                <mesh filename="package://open_manipulator_p_description/meshes/link4_papras.stl" scale="0.001 0.001 0.001"/>
            </geometry>
        </collision>
        <inertial>
            <origin rpy="0 0 0" xyz="0.12475 -0.05716 0.02979" />
            <!--<origin xyz="-0.07025 0.00034 -0.00021" rpy="0 0 0"/>-->
            <mass value="1.15977" />
            <inertia ixx="1.0" ixy="0.0" ixz="0.0" iyy="1.0" iyz="0.0" izz="1.0" />
            <!--<inertia ixx="0.00096726" ixy="0.00004383" ixz="-0.00002771" iyy="0.00318801" iyz="0.00000627" izz="0.00341484" />-->
        </inertial>
    </link>
    <!-- Joint 4 -->
    <joint name="robot2/joint4" type="revolute">
        <parent link="robot2/link4" />
        <child link="robot2/link5" />
        <origin rpy="0 0 0" xyz="0.19500 -0.05750 0.03000" />
        <axis xyz="1 0 0" />
        <limit effort="1000" lower="-1.57079632679" upper="1.57079632679" velocity="6.5" />
        <dynamics damping="0.7" />
    </joint>
    <!-- link 5 -->
    <link name="robot2/link5">
        <visual>
            <origin rpy="0 0 0" xyz="0 0 0" />
            <geometry>
                <mesh filename="package://open_manipulator_p_description/meshes/link5.stl" scale="0.001 0.001 0.001" />
            </geometry>
            <material name="grey" />
        </visual>
        <collision>
            <origin rpy="0 0 0" xyz="0 0 0" />
            <geometry>
                <mesh filename="package://open_manipulator_p_description/meshes/link5.stl" scale="0.001 0.001 0.001" />
            </geometry>
        </collision>
        <inertial>
            <origin rpy="0 0 0" xyz="0.05642 -0.00217 0.00002" />
            <!--<origin xyz="-0.00658 -0.04717 0.00002" rpy="0 0 0"/>-->
            <mass value="0.44688" />
            <inertia ixx="1.0" ixy="0.0" ixz="0.0" iyy="1.0" iyz="0.0" izz="1.0" />
            <!--<inertia ixx="0.00030285" ixy="0.00000761" ixz="0.00000031" iyy="0.00022339" iyz="-0.00000001" izz="0.00039766" />-->
        </inertial>
    </link>
    <!-- Joint 5 -->
    <joint name="robot2/joint5" type="revolute">
        <parent link="robot2/link5" />
        <child link="robot2/link6" />
        <origin rpy="0 0 0" xyz="0.06300 0.04500 0.00000" />
        <axis xyz="0 1 0" />
        <limit effort="1000" lower="-1.57079632679" upper="1.57079632679" velocity="6.5" />
        <dynamics damping="0.7" />
    </joint>
    <!-- link 6 -->
    <link name="robot2/link6">
        <visual>
            <origin xyz="-0.034 -0.098 -0.028" rpy="0 0 0"/>
            <geometry>
                <mesh filename="package://open_manipulator_p_description/meshes/link6_papras.stl" scale="0.001 0.001 0.001"/>
            </geometry>
            <material name="grey" />
        </visual>
        <collision>
            <origin xyz="-0.034 -0.098 -0.028" rpy="0 0 0"/>
            <geometry>
                <mesh filename="package://open_manipulator_p_description/meshes/link6_papras.stl" scale="0.001 0.001 0.001"/>
            </geometry>
        </collision>
        <inertial>
            <origin rpy="0 0 0" xyz="0.06831 -0.04457 0.00000" />
            <!--<origin xyz="-0.05469 0.00043 0.00000" rpy="0 0 0"/>-->
            <mass value="0.43273" />
            <inertia ixx="1.0" ixy="0.0" ixz="0.0" iyy="1.0" iyz="0.0" izz="1.0" />
            <!--<inertia ixx="0.00021512" ixy="0.00001009" ixz="0.00000000" iyy="0.00042827" iyz="0.00000000" izz="0.00051436" />-->
        </inertial>
    </link>
    <!-- Joint 6 -->
    <joint name="robot2/joint6" type="revolute">
        <parent link="robot2/link6" />
        <child link="robot2/end_link" />
        <origin rpy="0 0 0" xyz="0.12300 -0.04500 0.00000" />
        <axis xyz="1 0 0" />
        <limit effort="1000" lower="-1.57079632679" upper="1.57079632679" velocity="6.5" />
        <dynamics damping="0.7" />
    </joint>
    <!-- end link -->
    <link name="robot2/end_link">
        <visual>
            <origin rpy="0 0 0" xyz="0.0 0.0 0.0" />
            <geometry>
                <mesh filename="package://open_manipulator_p_description/meshes/end_link.stl" scale="0.001 0.001 0.001" />
            </geometry>
            <material name="grey" />
        </visual>
        <collision>
            <origin rpy="0 0 0" xyz="0.0 0.0 0.0" />
            <geometry>
                <mesh filename="package://open_manipulator_p_description/meshes/end_link.stl" scale="0.001 0.001 0.001" />
            </geometry>
        </collision>
        <inertial>
            <origin rpy="0 0 0" xyz="0.00337 0.00000 0.00000" />
            <mass value="0.01919" />
            <inertia ixx="1.0" ixy="0.0" ixz="0.0" iyy="1.0" iyz="0.0" izz="1.0" />
            <!--<inertia ixx="0.00000938" ixy="0.0" ixz="0.0" iyy="0.00000338" iyz="0.0" izz="0.00000635" />-->
        </inertial>
    </link>
    <joint name="robot3/world_fixed" type="fixed">
        <parent link="world" />
        <child link="robot3/link1" />
        <origin rpy="0 0 -1.57" xyz="0.3 0.0 0.853625" />
    </joint>
    <!-- link 1 -->
    <link name="robot3/link1">
        <visual>
            <origin rpy="0 0 0" xyz="0 0 0" />
            <geometry>
                <mesh filename="package://open_manipulator_p_description/meshes/link1.stl" scale="0.001 0.001 0.001" />
            </geometry>
            <material name="grey" />
        </visual>
        <collision>
            <origin rpy="0 0 0" xyz="0 0 0" />
            <geometry>
                <mesh filename="package://open_manipulator_p_description/meshes/link1.stl" scale="0.001 0.001 0.001" />
            </geometry>
        </collision>
        <inertial>
            <origin rpy="0 0 0" xyz="0.00023 0.00000 0.06223" />
            <mass value="0.85644" />
            <inertia ixx="1.0" ixy="0.0" ixz="0.0" iyy="1.0" iyz="0.0" izz="1.0" />
            <!--<inertia ixx="0.00121064" ixy="0.0" ixz="0.00001100" iyy="0.00120886" iyz="0.0" izz="0.00038103" />-->
        </inertial>
    </link>
    <!-- Joint 1 -->
    <joint name="robot3/joint1" type="revolute">
        <parent link="robot3/link1" />
        <child link="robot3/link2" />
        <origin rpy="0 0 0" xyz="0.0 0.0 0.126" />
        <axis xyz="0 0 1" />
        <limit effort="1000" lower="-1.57079632679" upper="1.57079632679" velocity="6.5" />
        <dynamics damping="0.7" />
    </joint>
    <!-- link 2 -->
    <link name="robot3/link2">
        <visual>
            <origin rpy="0 0 0" xyz="0 0 0" />
            <geometry>
                <mesh filename="package://open_manipulator_p_description/meshes/link2.stl" scale="0.001 0.001 0.001" />
            </geometry>
            <material name="grey" />
        </visual>
        <collision>
            <origin rpy="0 0 0" xyz="0 0 0" />
            <geometry>
                <mesh filename="package://open_manipulator_p_description/meshes/link2.stl" scale="0.001 0.001 0.001" />
            </geometry>
        </collision>
        <inertial>
            <origin rpy="0 0 0" xyz="0.00000 0.00080 0.03183" />
            <!--<origin xyz="0.00000 -0.06820 -0.00117" rpy="0 0 0"/>-->
            <mass value="0.94658" />
            <inertia ixx="1.0" ixy="0.0" ixz="0.0" iyy="1.0" iyz="0.0" izz="1.0" />
            <!--<inertia ixx="0.00152547" ixy="0.0" ixz="0.0" iyy="0.00045954" iyz="-0.00001086" izz="0.00151740" />-->
        </inertial>
    </link>
    <!-- Joint 2 -->
    <joint name="robot3/joint2" type="revolute">
        <parent link="robot3/link2" />
        <child link="robot3/link3" />
        <origin rpy="0 0 0" xyz="0.0 0.069 0.033" />
        <axis xyz="0 1 0" />
        <limit effort="1000" lower="-1.57079632679" upper="1.57079632679" velocity="6.5" />
        <dynamics damping="0.7" />
    </joint>
    <!-- link 3 -->
    <link name="robot3/link3">
        <visual>
            <origin xyz="0.067 0.008 -0.019" rpy="0 0 3.14"/>
            <geometry>
                <mesh filename="package://open_manipulator_p_description/meshes/link3_papras.stl" scale="0.001 0.001 0.001"/>
            </geometry>
            <material name="grey" />
        </visual>
        <collision>
            <origin xyz="0.067 0.008 -0.019" rpy="0 0 3.14"/>
            <geometry>
                <mesh filename="package://open_manipulator_p_description/meshes/link3_papras.stl" scale="0.001 0.001 0.001"/>
            </geometry>
        </collision>
        <inertial>
            <origin rpy="0 0 0" xyz="0.01768 -0.06881 0.20524" />
            <!--<origin xyz="-0.01232 -0.05731 -0.05876" rpy="0 0 0"/>-->
            <mass value="1.30260" />
            <inertia ixx="1.0" ixy="0.0" ixz="0.0" iyy="1.0" iyz="0.0" izz="1.0" />
            <!--<inertia ixx="0.01111021" ixy="0.00001331" ixz="-0.00134208" iyy="0.01046642" iyz="0.00016235" izz="0.00202081" />-->
        </inertial>
    </link>
    <!-- Joint 3 -->
    <joint name="robot3/joint3" type="revolute">
        <parent link="robot3/link3" />
        <child link="robot3/link4" />
        <origin rpy="0 0 0" xyz="0.03000 -0.01150 0.26400" />
        <axis xyz="0 1 0" />
        <limit effort="1000" lower="-1.57079632679" upper="1.57079632679" velocity="6.5" />
        <dynamics damping="0.7" />
    </joint>
    <!-- link 4 -->
    <link name="robot3/link4">
        <visual>
            <origin xyz="0.227 0.0085 -0.024" rpy="0 0 3.14"/>
            <geometry>
                <mesh filename="package://open_manipulator_p_description/meshes/link4_papras.stl" scale="0.001 0.001 0.001"/>
            </geometry>
            <material name="grey" />
        </visual>
        <collision>
            <origin xyz="0.227 0.0085 -0.024" rpy="0 0 3.14"/>
            <geometry>
                <mesh filename="package://open_manipulator_p_description/meshes/link4_papras.stl" scale="0.001 0.001 0.001"/>
            </geometry>
        </collision>
        <inertial>
            <origin rpy="0 0 0" xyz="0.12475 -0.05716 0.02979" />
            <!--<origin xyz="-0.07025 0.00034 -0.00021" rpy="0 0 0"/>-->
            <mass value="1.15977" />
            <inertia ixx="1.0" ixy="0.0" ixz="0.0" iyy="1.0" iyz="0.0" izz="1.0" />
            <!--<inertia ixx="0.00096726" ixy="0.00004383" ixz="-0.00002771" iyy="0.00318801" iyz="0.00000627" izz="0.00341484" />-->
        </inertial>
    </link>
    <!-- Joint 4 -->
    <joint name="robot3/joint4" type="revolute">
        <parent link="robot3/link4" />
        <child link="robot3/link5" />
        <origin rpy="0 0 0" xyz="0.19500 -0.05750 0.03000" />
        <axis xyz="1 0 0" />
        <limit effort="1000" lower="-1.57079632679" upper="1.57079632679" velocity="6.5" />
        <dynamics damping="0.7" />
    </joint>
    <!-- link 5 -->
    <link name="robot3/link5">
        <visual>
            <origin rpy="0 0 0" xyz="0 0 0" />
            <geometry>
                <mesh filename="package://open_manipulator_p_description/meshes/link5.stl" scale="0.001 0.001 0.001" />
            </geometry>
            <material name="grey" />
        </visual>
        <collision>
            <origin rpy="0 0 0" xyz="0 0 0" />
            <geometry>
                <mesh filename="package://open_manipulator_p_description/meshes/link5.stl" scale="0.001 0.001 0.001" />
            </geometry>
        </collision>
        <inertial>
            <origin rpy="0 0 0" xyz="0.05642 -0.00217 0.00002" />
            <!--<origin xyz="-0.00658 -0.04717 0.00002" rpy="0 0 0"/>-->
            <mass value="0.44688" />
            <inertia ixx="1.0" ixy="0.0" ixz="0.0" iyy="1.0" iyz="0.0" izz="1.0" />
            <!--<inertia ixx="0.00030285" ixy="0.00000761" ixz="0.00000031" iyy="0.00022339" iyz="-0.00000001" izz="0.00039766" />-->
        </inertial>
    </link>
    <!-- Joint 5 -->
    <joint name="robot3/joint5" type="revolute">
        <parent link="robot3/link5" />
        <child link="robot3/link6" />
        <origin rpy="0 0 0" xyz="0.06300 0.04500 0.00000" />
        <axis xyz="0 1 0" />
        <limit effort="1000" lower="-1.57079632679" upper="1.57079632679" velocity="6.5" />
        <dynamics damping="0.7" />
    </joint>
    <!-- link 6 -->
    <link name="robot3/link6">
        <visual>
            <origin xyz="-0.034 -0.098 -0.028" rpy="0 0 0"/>
            <geometry>
                <mesh filename="package://open_manipulator_p_description/meshes/link6_papras.stl" scale="0.001 0.001 0.001"/>
            </geometry>
            <material name="grey" />
        </visual>
        <collision>
            <origin xyz="-0.034 -0.098 -0.028" rpy="0 0 0"/>
            <geometry>
                <mesh filename="package://open_manipulator_p_description/meshes/link6_papras.stl" scale="0.001 0.001 0.001"/>
            </geometry>
        </collision>
        <inertial>
            <origin rpy="0 0 0" xyz="0.06831 -0.04457 0.00000" />
            <!--<origin xyz="-0.05469 0.00043 0.00000" rpy="0 0 0"/>-->
            <mass value="0.43273" />
            <inertia ixx="1.0" ixy="0.0" ixz="0.0" iyy="1.0" iyz="0.0" izz="1.0" />
            <!--<inertia ixx="0.00021512" ixy="0.00001009" ixz="0.00000000" iyy="0.00042827" iyz="0.00000000" izz="0.00051436" />-->
        </inertial>
    </link>
    <!-- Joint 6 -->
    <joint name="robot3/joint6" type="revolute">
        <parent link="robot3/link6" />
        <child link="robot3/end_link" />
        <origin rpy="0 0 0" xyz="0.12300 -0.04500 0.00000" />
        <axis xyz="1 0 0" />
        <limit effort="1000" lower="-1.57079632679" upper="1.57079632679" velocity="6.5" />
        <dynamics damping="0.7" />
    </joint>
    <!-- end link -->
    <link name="robot3/end_link">
        <visual>
            <origin rpy="0 0 0" xyz="0.0 0.0 0.0" />
            <geometry>
                <mesh filename="package://open_manipulator_p_description/meshes/end_link.stl" scale="0.001 0.001 0.001" />
            </geometry>
            <material name="grey" />
        </visual>
        <collision>
            <origin rpy="0 0 0" xyz="0.0 0.0 0.0" />
            <geometry>
                <mesh filename="package://open_manipulator_p_description/meshes/end_link.stl" scale="0.001 0.001 0.001" />
            </geometry>
        </collision>
        <inertial>
            <origin rpy="0 0 0" xyz="0.00337 0.00000 0.00000" />
            <mass value="0.01919" />
            <inertia ixx="1.0" ixy="0.0" ixz="0.0" iyy="1.0" iyz="0.0" izz="1.0" />
            <!--<inertia ixx="0.00000938" ixy="0.0" ixz="0.0" iyy="0.00000338" iyz="0.0" izz="0.00000635" />-->
        </inertial>
    </link>
    <transmission name="trans_robot1/joint1">
        <type>transmission_interface/SimpleTransmission</type>
        <joint name="robot1/joint1">
            <hardwareInterface>hardware_interface/PositionJointInterface</hardwareInterface>
        </joint>
        <actuator name="robot1/joint1_motor">
            <hardwareInterface>hardware_interface/PositionJointInterface</hardwareInterface>
            <mechanicalReduction>1</mechanicalReduction>
        </actuator>
    </transmission>
    <transmission name="trans_robot1/joint2">
        <type>transmission_interface/SimpleTransmission</type>
        <joint name="robot1/joint2">
            <hardwareInterface>hardware_interface/PositionJointInterface</hardwareInterface>
        </joint>
        <actuator name="robot1/joint2_motor">
            <hardwareInterface>hardware_interface/PositionJointInterface</hardwareInterface>
            <mechanicalReduction>1</mechanicalReduction>
        </actuator>
    </transmission>
    <transmission name="trans_robot1/joint3">
        <type>transmission_interface/SimpleTransmission</type>
        <joint name="robot1/joint3">
            <hardwareInterface>hardware_interface/PositionJointInterface</hardwareInterface>
        </joint>
        <actuator name="robot1/joint3_motor">
            <hardwareInterface>hardware_interface/PositionJointInterface</hardwareInterface>
            <mechanicalReduction>1</mechanicalReduction>
        </actuator>
    </transmission>
    <transmission name="trans_robot1/joint4">
        <type>transmission_interface/SimpleTransmission</type>
        <joint name="robot1/joint4">
            <hardwareInterface>hardware_interface/PositionJointInterface</hardwareInterface>
        </joint>
        <actuator name="robot1/joint4_motor">
            <hardwareInterface>hardware_interface/PositionJointInterface</hardwareInterface>
            <mechanicalReduction>1</mechanicalReduction>
        </actuator>
    </transmission>
    <transmission name="trans_robot1/joint5">
        <type>transmission_interface/SimpleTransmission</type>
        <joint name="robot1/joint5">
            <hardwareInterface>hardware_interface/PositionJointInterface</hardwareInterface>
        </joint>
        <actuator name="robot1/joint5_motor">
            <hardwareInterface>hardware_interface/PositionJointInterface</hardwareInterface>
            <mechanicalReduction>1</mechanicalReduction>
        </actuator>
    </transmission>
    <transmission name="trans_robot1/joint6">
        <type>transmission_interface/SimpleTransmission</type>
        <joint name="robot1/joint6">
            <hardwareInterface>hardware_interface/PositionJointInterface</hardwareInterface>
        </joint>
        <actuator name="robot1/joint6_motor">
            <hardwareInterface>hardware_interface/PositionJointInterface</hardwareInterface>
            <mechanicalReduction>1</mechanicalReduction>
        </actuator>
    </transmission>
    <transmission name="trans_robot2/joint1">
        <type>transmission_interface/SimpleTransmission</type>
        <joint name="robot2/joint1">
            <hardwareInterface>hardware_interface/PositionJointInterface</hardwareInterface>
        </joint>
        <actuator name="robot2/joint1_motor">
            <hardwareInterface>hardware_interface/PositionJointInterface</hardwareInterface>
            <mechanicalReduction>1</mechanicalReduction>
        </actuator>
    </transmission>
    <transmission name="trans_robot2/joint2">
        <type>transmission_interface/SimpleTransmission</type>
        <joint name="robot2/joint2">
            <hardwareInterface>hardware_interface/PositionJointInterface</hardwareInterface>
        </joint>
        <actuator name="robot2/joint2_motor">
            <hardwareInterface>hardware_interface/PositionJointInterface</hardwareInterface>
            <mechanicalReduction>1</mechanicalReduction>
        </actuator>
    </transmission>
    <transmission name="trans_robot2/joint3">
        <type>transmission_interface/SimpleTransmission</type>
        <joint name="robot2/joint3">
            <hardwareInterface>hardware_interface/PositionJointInterface</hardwareInterface>
        </joint>
        <actuator name="robot2/joint3_motor">
            <hardwareInterface>hardware_interface/PositionJointInterface</hardwareInterface>
            <mechanicalReduction>1</mechanicalReduction>
        </actuator>
    </transmission>
    <transmission name="trans_robot2/joint4">
        <type>transmission_interface/SimpleTransmission</type>
        <joint name="robot2/joint4">
            <hardwareInterface>hardware_interface/PositionJointInterface</hardwareInterface>
        </joint>
        <actuator name="robot2/joint4_motor">
            <hardwareInterface>hardware_interface/PositionJointInterface</hardwareInterface>
            <mechanicalReduction>1</mechanicalReduction>
        </actuator>
    </transmission>
    <transmission name="trans_robot2/joint5">
        <type>transmission_interface/SimpleTransmission</type>
        <joint name="robot2/joint5">
            <hardwareInterface>hardware_interface/PositionJointInterface</hardwareInterface>
        </joint>
        <actuator name="robot2/joint5_motor">
            <hardwareInterface>hardware_interface/PositionJointInterface</hardwareInterface>
            <mechanicalReduction>1</mechanicalReduction>
        </actuator>
    </transmission>
    <transmission name="trans_robot2/joint6">
        <type>transmission_interface/SimpleTransmission</type>
        <joint name="robot2/joint6">
            <hardwareInterface>hardware_interface/PositionJointInterface</hardwareInterface>
        </joint>
        <actuator name="robot2/joint6_motor">
            <hardwareInterface>hardware_interface/PositionJointInterface</hardwareInterface>
            <mechanicalReduction>1</mechanicalReduction>
        </actuator>
    </transmission>
    <transmission name="trans_robot3/joint1">
        <type>transmission_interface/SimpleTransmission</type>
        <joint name="robot3/joint1">
            <hardwareInterface>hardware_interface/PositionJointInterface</hardwareInterface>
        </joint>
        <actuator name="robot3/joint1_motor">
            <hardwareInterface>hardware_interface/PositionJointInterface</hardwareInterface>
            <mechanicalReduction>1</mechanicalReduction>
        </actuator>
    </transmission>
    <transmission name="trans_robot3/joint2">
        <type>transmission_interface/SimpleTransmission</type>
        <joint name="robot3/joint2">
            <hardwareInterface>hardware_interface/PositionJointInterface</hardwareInterface>
        </joint>
        <actuator name="robot3/joint2_motor">
            <hardwareInterface>hardware_interface/PositionJointInterface</hardwareInterface>
            <mechanicalReduction>1</mechanicalReduction>
        </actuator>
    </transmission>
    <transmission name="trans_robot3/joint3">
        <type>transmission_interface/SimpleTransmission</type>
        <joint name="robot3/joint3">
            <hardwareInterface>hardware_interface/PositionJointInterface</hardwareInterface>
        </joint>
        <actuator name="robot3/joint3_motor">
            <hardwareInterface>hardware_interface/PositionJointInterface</hardwareInterface>
            <mechanicalReduction>1</mechanicalReduction>
        </actuator>
    </transmission>
    <transmission name="trans_robot3/joint4">
        <type>transmission_interface/SimpleTransmission</type>
        <joint name="robot3/joint4">
            <hardwareInterface>hardware_interface/PositionJointInterface</hardwareInterface>
        </joint>
        <actuator name="robot3/joint4_motor">
            <hardwareInterface>hardware_interface/PositionJointInterface</hardwareInterface>
            <mechanicalReduction>1</mechanicalReduction>
        </actuator>
    </transmission>
    <transmission name="trans_robot3/joint5">
        <type>transmission_interface/SimpleTransmission</type>
        <joint name="robot3/joint5">
            <hardwareInterface>hardware_interface/PositionJointInterface</hardwareInterface>
        </joint>
        <actuator name="robot3/joint5_motor">
            <hardwareInterface>hardware_interface/PositionJointInterface</hardwareInterface>
            <mechanicalReduction>1</mechanicalReduction>
        </actuator>
    </transmission>
    <transmission name="trans_robot3/joint6">
        <type>transmission_interface/SimpleTransmission</type>
        <joint name="robot3/joint6">
            <hardwareInterface>hardware_interface/PositionJointInterface</hardwareInterface>
        </joint>
        <actuator name="robot3/joint6_motor">
            <hardwareInterface>hardware_interface/PositionJointInterface</hardwareInterface>
            <mechanicalReduction>1</mechanicalReduction>
        </actuator>
    </transmission>
    <gazebo>
        <plugin name="gazebo_ros_control" filename="libgazebo_ros_control.so">
            <robotNamespace>/</robotNamespace>
        </plugin>
    </gazebo>
</robot>